Workbook
Name saldo_inicial: 'CONFIG'!$B$11
Name ano_referencia: 'CONFIG'!$B$12
Name modo_apuracao: 'CONFIG'!$B$13
Name taxa_debito: 'CONFIG'!$B$16
Name prazo_debito_dias: 'CONFIG'!$D$16
Name taxa_credito_vista: 'CONFIG'!$B$17
Name prazo_credito_dias: 'CONFIG'!$D$17
Name taxa_credito_parcelado: 'CONFIG'!$B$18
Name taxa_ifood: 'CONFIG'!$B$21
Name prazo_ifood_dias: 'CONFIG'!$D$21
Name taxa_ubereats: 'CONFIG'!$B$22
Name prazo_ubereats_dias: 'CONFIG'!$D$22
Name taxa_99food: 'CONFIG'!$B$23
Name prazo_99food_dias: 'CONFIG'!$D$23

Sheet INÍCIO
A1: W.D.S. WDS Fluxo de Caixa VERSÃO DEMONSTRATIVA
B4: Controle o fluxo de caixa do seu negócio de alimentação em um só lugar: lance vendas e despesas, acompanhe o previsto x realizado respeitando o prazo de repasse do cartão e dos apps de delivery, e organize contas a pagar e a receber.
B6: ◆ Esta é a versão demonstrativa. Os dados já preenchidos na aba LANÇAMENTOS são de exemplo — apague e coloque os seus. Todas as fórmulas funcionam de verdade: mexa nas suas taxas na aba CONFIG e veja os números mudarem.
B8: O QUE MUDA NA VERSÃO COMPLETA
B9: • Lançamentos: 30 nesta demo → 3.000 na completa (cerca de 1 ano)
B10: • Contas a pagar/receber: só visível aqui → totalmente funcional na completa
B11: • Relatório em PDF: com marca d'água aqui → limpo, pronto para o contador
B12: • Ano de referência: fixo aqui → editável na completa
B14: COMO USAR
B15: 1. Configure suas taxas, prazos e categorias na aba CONFIG.
B16: 2. Lance vendas e despesas todo dia na aba LANÇAMENTOS.
B17: 3. Registre contas a vencer na aba CONTAS A PAGAR/RECEBER.
B18: 4. Acompanhe o resultado em DASHBOARD.
... B35: WDS Fluxo de Caixa — versão 1.0 | Suporte: wwwilliansantosdias@gmail.com

Sheet CONFIG
A1: W.D.S. — CONFIGURAÇÃO
A2: Ir para: | B2: INÍCIO | C2: LANÇAMENTOS | D2: CONTAS A PAGAR-RECEBER | E2: FLUXO DE CAIXA | F2: DASHBOARD | G2: RELATÓRIO | H2: DÚVIDAS
A3: Preencha as células amarelas antes de usar a planilha. Azul é o que você edita no dia a dia; preto é fórmula e não deve ser alterado.
A5: DADOS DO NEGÓCIO
A6: Nome do negócio | B6: Meu Restaurante
A7: Responsável
A8: Tipo de negócio | B8: Restaurante
A10: PARÂMETROS GERAIS
A11: Saldo inicial em caixa/banco (R$) | B11: 12000 | C11: Dinheiro que já existe antes de começar a usar a planilha.
A12: Ano de referência (aba FLUXO DE CAIXA) | B12: 2026 | C12: Fixo nesta versão demonstrativa. Editável na versão completa.
A13: Modo de apuração do Realizado | B13: Data Prevista | C13: "Data Prevista" conta tudo cujo prazo já venceu, sem exigir nada do usuário. "Conferencia" só conta o que foi marcado como Conferido = Sim em LANÇAMENTOS.
A15: TAXAS E PRAZOS — MAQUININHA DE CARTÃO
A16: Taxa débito (%) | B16: 0.015 | C16: Prazo débito (dias até o repasse) | D16: 1
A17: Taxa crédito à vista (%) | B17: 0.035 | C17: Prazo crédito, à vista e parcelado (dias até o repasse) | D17: 30
A18: Taxa crédito parcelado (%) | B18: 0.055 | C18: Usa o mesmo prazo do crédito à vista, na linha acima.
A20: TAXAS E PRAZOS — APPS DE DELIVERY
A21: Comissão iFood (%) | B21: 0.12 | C21: Prazo repasse iFood (dias) | D21: 7
A22: Comissão Uber Eats (%) | B22: 0.15 | C22: Prazo repasse Uber Eats (dias) | D22: 7
A23: Comissão 99Food (%) | B23: 0.12 | C23: Prazo repasse 99Food (dias) | D23: 14
A25: CATEGORIAS (NATUREZA DO LANÇAMENTO)
A26: Editável e expansível. Usada nas colunas Categoria de LANÇAMENTOS.
B27: Venda de Produto
B28: Despesa Fixa
B29: Despesa Variável
B30: Compra de Insumo
B31: Empréstimo
B32: Outros
A43: CANAIS DE VENDA
A44: Editável e expansível. Não renomeie iFood, Uber Eats e 99Food: esses nomes exatos são usados nas fórmulas de taxa e prazo de LANÇAMENTOS. Novos canais podem ser adicionados livremente nas linhas em branco.
B45: Balcão
B46: iFood
B47: Uber Eats
B48: 99Food
B49: WhatsApp
B50: Delivery Próprio
B51: Interno/N-A
A58: FORMAS DE PAGAMENTO (FIXAS)
A59: Lista fixa usada na coluna Forma de Pagamento de LANÇAMENTOS — os nomes exatos abaixo são usados nas fórmulas de taxa e prazo, por isso não são editáveis aqui.
B60: Dinheiro
B61: PIX
...

Sheet LANÇAMENTOS
A1: W.D.S. — LANÇAMENTOS
A2: Ir para: | B2: INÍCIO | C2: CONFIG | D2: CONTAS A PAGAR-RECEBER | E2: FLUXO DE CAIXA | F2: DASHBOARD | G2: RELATÓRIO | H2: DÚVIDAS
A3: VERSÃO DEMONSTRATIVA — limitada a 30 lançamentos. Os dados abaixo são de exemplo: apague e coloque os seus. Todas as fórmulas funcionam normalmente.
A4: Data | B4: Tipo | C4: Categoria | D4: Canal | E4: Forma de Pagamento | F4: Valor Bruto (R$) | G4: Taxa Aplicada | H4: Valor Líquido (R$) | I4: Data Prevista de Caixa | J4: Status | K4: Conferido no Extrato | L4: Responsável pelo Lançamento | M4: Nº do Comprovante/NF | N4: Observação
A5: 46235 | B5: Entrada | C5: Venda de Produto | D5: Balcão | E5: Dinheiro | F5: 2340 | G5: =IF($A5="","",IF($B5="Saída",0,IF($D5="iFood",taxa_ifood,IF($D5="Uber Eats",taxa_ubereats,IF($D5="99Food",taxa_99food,IF($E5="Débito",taxa_debito,IF($E5="Crédito à vista",taxa_credito_vista,IF($E5="Crédito parcelado",taxa_credito_parcelado,0)))))))) | H5: =IF($A5="","",IF($B5="Saída",$F5,$F5*(1-$G5))) | I5: =IF($A5="","",IF($B5="Saída",$A5,IF($D5="iFood",$A5+prazo_ifood_dias,IF($D5="Uber Eats",$A5+prazo_ubereats_dias,IF($D5="99Food",$A5+prazo_99food_dias,IF($E5="Débito",$A5+prazo_debito_dias,IF(OR($E5="Crédito à vista",$E5="Crédito parcelado"),$A5+prazo_credito_dias,$A5))))))) | J5: =IF($A5="","",IF($K5="Sim","Realizado",IF($I5<=TODAY(),"A Confirmar","Previsto"))) | K5: Sim | L5: Ana (caixa) | N5: Vendas do dia — balcão
A6: 46235 | B6: Saída | C6: Despesa Fixa | D6: Interno/N-A | E6: PIX | F6: 3800 | G6: =IF($A6="","",IF($B6="Saída",0,IF($D6="iFood",taxa_ifood,IF($D6="Uber Eats",taxa_ubereats,IF($D6="99Food",taxa_99food,IF($E6="Débito",taxa_debito,IF($E6="Crédito à vista",taxa_credito_vista,IF($E6="Crédito parcelado",taxa_credito_parcelado,0)))))))) | H6: =IF($A6="","",IF($B6="Saída",$F6,$F6*(1-$G6))) | I6: =IF($A6="","",IF($B6="Saída",$A6,IF($D6="iFood",$A6+prazo_ifood_dias,IF($D6="Uber Eats",$A6+prazo_ubereats_dias,IF($D6="99Food",$A6+prazo_99food_dias,IF($E6="Débito",$A6+prazo_debito_dias,IF(OR($E6="Crédito à vista",$E6="Crédito parcelado"),$A6+prazo_credito_dias,$A6))))))) | J6: =IF($A6="","",IF($K6="Sim","Realizado",IF($I6<=TODAY(),"A Confirmar","Previsto"))) | K6: Sim | L6: Marcos (gerente) | N6: Aluguel do ponto
A7: 46236 | B7: Entrada | C7: Venda de Produto | D7: Balcão | E7: Débito | F7: 1980 | G7: =IF($A7="","",IF($B7="Saída",0,IF($D7="iFood",taxa_ifood,IF($D7="Uber Eats",taxa_ubereats,IF($D7="99Food",taxa_99food,IF($E7="Débito",taxa_debito,IF($E7="Crédito à vista",taxa_credito_vista,IF($E7="Crédito parcelado",taxa_credito_parcelado,0)))))))) | H7: =IF($A7="","",IF($B7="Saída",$F7,$F7*(1-$G7))) | I7: =IF($A7="","",IF($B7="Saída",$A7,IF($D7="iFood",$A7+prazo_ifood_dias,IF($D7="Uber Eats",$A7+prazo_ubereats_dias,IF($D7="99Food",$A7+prazo_99food_dias,IF($E7="Débito",$A7+prazo_debito_dias,IF(OR($E7="Crédito à vista",$E7="Crédito parcelado"),$A7+prazo_credito_dias,$A7))))))) | J7: =IF($A7="","",IF($K7="Sim","Realizado",IF($I7<=TODAY(),"A Confirmar","Previsto"))) | K7: Sim | L7: Ana (caixa) | N7: Vendas do dia — cartão débito
A8: 46236 | B8: Entrada | C8: Venda de Produto | D8: iFood | E8: Crédito à vista | F8: 1650 | G8: =IF($A8="","",IF($B8="Saída",0,IF($D8="iFood",taxa_ifood,IF($D8="Uber Eats",taxa_ubereats,IF($D8="99Food",taxa_99food,IF($E8="Débito",taxa_debito,IF($E8="Crédito à vista",taxa_credito_vista,IF($E8="Crédito parcelado",taxa_credito_parcelado,0)))))))) | H8: =IF($A8="","",IF($B8="Saída",$F8,$F8*(1-$G8))) | I8: =IF($A8="","",IF($B8="Saída",$A8,IF($D8="iFood",$A8+prazo_ifood_dias,IF($D8="Uber Eats",$A8+prazo_ubereats_dias,IF($D8="99Food",$A8+prazo_99food_dias,IF($E8="Débito",$A8+prazo_debito_dias,IF(OR($E8="Crédito à vista",$E8="Crédito parcelado"),$A8+prazo_credito_dias,$A8))))))) | J8: =IF($A8="","",IF($K8="Sim","Realizado",IF($I8<=TODAY(),"A Confirmar","Previsto"))) | K8: Sim | L8: Marcos (gerente) | N8: Repasse iFood
A9: 46237 | B9: Saída | C9: Compra de Insumo | D9: Interno/N-A | E9: Dinheiro | F9: 720 | G9: =IF($A9="","",IF($B9="Saída",0,IF($D9="iFood",taxa_ifood,IF($D9="Uber Eats",taxa_ubereats,IF($D9="99Food",taxa_99food,IF($E9="Débito",taxa_debito,IF($E9="Crédito à vista",taxa_credito_vista,IF($E9="Crédito parcelado",taxa_credito_parcelado,0)))))))) | H9: =IF($A9="","",IF($B9="Saída",$F9,$F9*(1-$G9))) | I9: =IF($A9="","",IF($B9="Saída",$A9,IF($D9="iFood",$A9+prazo_ifood_dias,IF($D9="Uber Eats",$A9+prazo_ubereats_dias,IF($D9="99Food",$A9+prazo_99food_dias,IF($E9="Débito",$A9+prazo_debito_dias,IF(OR($E9="Crédito à vista",$E9="Crédito parcelado"),$A9+prazo_credito_dias,$A9))))))) | J9: =IF($A9="","",IF($K9="Sim","Realizado",IF($I9<=TODAY(),"A Confirmar","Previsto"))) | K9: Sim | L9: Ana (caixa) | N9: Hortifruti — feira
A10: 46238 | B10: Entrada | C10: Venda de Produto | D10: Balcão | E10: Crédito à vista | F10: 1430 | G10: =IF($A10="","",IF($B10="Saída",0,IF($D10="iFood",taxa_ifood,IF($D10="Uber Eats",taxa_ubereats,IF($D10="99Food",taxa_99food,IF($E10="Débito",taxa_debito,IF($E10="Crédito à vista",taxa_credito_vista,IF($E10="Crédito parcelado",taxa_credito_parcelado,0)))))))) | H10: =IF($A10="","",IF($B10="Saída",$F10,$F10*(1-$G10))) | I10: =IF($A10="","",IF($B10="Saída",$A10,IF($D10="iFood",$A10+prazo_ifood_dias,IF($D10="Uber Eats",$A10+prazo_ubereats_dias,IF($D10="99Food",$A10+prazo_99food_dias,IF($E10="Débito",$A10+prazo_debito_dias,IF(OR($E10="Crédito à vista",$E10="Crédito parcelado"),$A10+prazo_credito_dias,$A10))))))) | J10: =IF($A10="","",IF($K10="Sim","Realizado",IF($I10<=TODAY(),"A Confirmar","Previsto"))) | K10: Não | L10: Marcos (gerente) | N10: Vendas do dia — crédito
A11: 46239 | B11: Entrada | C11: Venda de Produto | D11: Uber Eats | E11: Dinheiro | F11: 1290 | G11: =IF($A11="","",IF($B11="Saída",0,IF($D11="iFood",taxa_ifood,IF($D11="Uber Eats",taxa_ubereats,IF($D11="99Food",taxa_99food,IF($E11="Débito",taxa_debito,IF($E11="Crédito à vista",taxa_credito_vista,IF($E11="Crédito parcelado",taxa_credito_parcelado,0)))))))) | H11: =IF($A11="","",IF($B11="Saída",$F11,$F11*(1-$G11))) | I11: =IF($A11="","",IF($B11="Saída",$A11,IF($D11="iFood",$A11+prazo_ifood_dias,IF($D11="Uber Eats",$A11+prazo_ubereats_dias,IF($D11="99Food",$A11+prazo_99food_dias,IF($E11="Débito",$A11+prazo_debito_dias,IF(OR($E11="Crédito à vista",$E11="Crédito parcelado"),$A11+prazo_credito_dias,$A11))))))) | J11: =IF($A11="","",IF($K11="Sim","Realizado",IF($I11<=TODAY(),"A Confirmar","Previsto"))) | K11: Não | L11: Ana (caixa) | N11: Pedidos Uber Eats
A12: 46240 | B12: Saída | C12: Compra de Insumo | D12: Interno/N-A | E12: PIX | F12: 1850 | G12: =IF($A12="","",IF($B12="Saída",0,IF($D12="iFood",taxa_ifood,IF($D12="Uber Eats",taxa_ubereats,IF($D12="99Food",taxa_99food,IF($E12="Débito",taxa_debito,IF($E12="Crédito à vista",taxa_credito_vista,IF($E12="Crédito parcelado",taxa_credito_parcelado,0)))))))) | H12: =IF($A12="","",IF($B12="Saída",$F12,$F12*(1-$G12))) | I12: =IF($A12="","",IF($B12="Saída",$A12,IF($D12="iFood",$A12+prazo_ifood_dias,IF($D12="Uber Eats",$A12+prazo_ubereats_dias,IF($D12="99Food",$A12+prazo_99food_dias,IF($E12="Débito",$A12+prazo_debito_dias,IF(OR($E12="Crédito à vista",$E12="Crédito parcelado"),$A12+prazo_credito_dias,$A12))))))) | J12: =IF($A12="","",IF($K12="Sim","Realizado",IF($I12<=TODAY(),"A Confirmar","Previsto"))) | K12: Sim | L12: Marcos (gerente) | N12: Frigorífico — carnes
A13: 46241 | B13: Entrada | C13: Venda de Produto | D13: Balcão | E13: PIX | F13: 2280 | G13: =IF($A13="","",IF($B13="Saída",0,IF($D13="iFood",taxa_ifood,IF($D13="Uber Eats",taxa_ubereats,IF($D13="99Food",taxa_99food,IF($E13="Débito",taxa_debito,IF($E13="Crédito à vista",taxa_credito_vista,IF($E13="Crédito parcelado",taxa_credito_parcelado,0)))))))) | H13: =IF($A13="","",IF($B13="Saída",$F13,$F13*(1-$G13))) | I13: =IF($A13="","",IF($B13="Saída",$A13,IF($D13="iFood",$A13+prazo_ifood_dias,IF($D13="Uber Eats",$A13+prazo_ubereats_dias,IF($D13="99Food",$A13+prazo_99food_dias,IF($E13="Débito",$A13+prazo_debito_dias,IF(OR($E13="Crédito à vista",$E13="Crédito parcelado"),$A13+prazo_credito_dias,$A13))))))) | J13: =IF($A13="","",IF($K13="Sim","Realizado",IF($I13<=TODAY(),"A Confirmar","Previsto"))) | K13: Sim | L13: Ana (caixa) | N13: Vendas do dia — PIX
A14: 46242 | B14: Entrada | C14: Venda de Produto | D14: 99Food | E14: PIX | F14: 940 | G14: =IF($A14="","",IF($B14="Saída",0,IF($D14="iFood",taxa_ifood,IF($D14="Uber Eats",taxa_ubereats,IF($D14="99Food",taxa_99food,IF($E14="Débito",taxa_debito,IF($E14="Crédito à vista",taxa_credito_vista,IF($E14="Crédito parcelado",taxa_credito_parcelado,0)))))))) | H14: =IF($A14="","",IF($B14="Saída",$F14,$F14*(1-$G14))) | I14: =IF($A14="","",IF($B14="Saída",$A14,IF($D14="iFood",$A14+prazo_ifood_dias,IF($D14="Uber Eats",$A14+prazo_ubereats_dias,IF($D14="99Food",$A14+prazo_99food_dias,IF($E14="Débito",$A14+prazo_debito_dias,IF(OR($E14="Crédito à vista",$E14="Crédito parcelado"),$A14+prazo_credito_dias,$A14))))))) | J14: =IF($A14="","",IF($K14="Sim","Realizado",IF($I14<=TODAY(),"A Confirmar","Previsto"))) | K14: Não | L14: Marcos (gerente) | N14: Pedidos 99Food
A15: 46243 | B15: Saída | C15: Despesa Variável | D15: Interno/N-A | E15: Débito | F15: 430 | G15: =IF($A15="","",IF($B15="Saída",0,IF($D15="iFood",taxa_ifood,IF($D15="Uber Eats",taxa_ubereats,IF($D15="99Food",taxa_99food,IF($E15="Débito",taxa_debito,IF($E15="Crédito à vista",taxa_credito_vista,IF($E15="Crédito parcelado",taxa_credito_parcelado,0)))))))) | H15: =IF($A15="","",IF($B15="Saída",$F15,$F15*(1-$G15))) | I15: =IF($A15="","",IF($B15="Saída",$A15,IF($D15="iFood",$A15+prazo_ifood_dias,IF($D15="Uber Eats",$A15+prazo_ubereats_dias,IF($D15="99Food",$A15+prazo_99food_dias,IF($E15="Débito",$A15+prazo_debito_dias,IF(OR($E15="Crédito à vista",$E15="Crédito parcelado"),$A15+prazo_credito_dias,$A15))))))) | J15: =IF($A15="","",IF($K15="Sim","Realizado",IF($I15<=TODAY(),"A Confirmar","Previsto"))) | K15: Sim | L15: Ana (caixa) | N15: Gás e descartáveis
A16: 46244 | B16: Entrada | C16: Venda de Produto | D16: WhatsApp | E16: PIX | F16: 1460 | G16: =IF($A16="","",IF($B16="Saída",0,IF($D16="iFood",taxa_ifood,IF($D16="Uber Eats",taxa_ubereats,IF($D16="99Food",taxa_99food,IF($E16="Débito",taxa_debito,IF($E16="Crédito à vista",taxa_credito_vista,IF($E16="Crédito parcelado",taxa_credito_parcelado,0)))))))) | H16: =IF($A16="","",IF($B16="Saída",$F16,$F16*(1-$G16))) | I16: =IF($A16="","",IF($B16="Saída",$A16,IF($D16="iFood",$A16+prazo_ifood_dias,IF($D16="Uber Eats",$A16+prazo_ubereats_dias,IF($D16="99Food",$A16+prazo_99food_dias,IF($E16="Débito",$A16+prazo_debito_dias,IF(OR($E16="Crédito à vista",$E16="Crédito parcelado"),$A16+prazo_credito_dias,$A16))))))) | J16: =IF($A16="","",IF($K16="Sim","Realizado",IF($I16<=TODAY(),"A Confirmar","Previsto"))) | K16: Sim | L16: Marcos (gerente) | N16: Encomendas WhatsApp
... A34: 46256 | B34: Saída | C34: Outros | D34: Interno/N-A | E34: Dinheiro | F34: 200 | G34: =IF($A34="","",IF($B34="Saída",0,IF($D34="iFood",taxa_ifood,IF($D34="Uber Eats",taxa_ubereats,IF($D34="99Food",taxa_99food,IF($E34="Débito",taxa_debito,IF($E34="Crédito à vista",taxa_credito_vista,IF($E34="Crédito parcelado",taxa_credito_parcelado,0)))))))) | H34: =IF($A34="","",IF($B34="Saída",$F34,$F34*(1-$G34))) | I34: =IF($A34="","",IF($B34="Saída",$A34,IF($D34="iFood",$A34+prazo_ifood_dias,IF($D34="Uber Eats",$A34+prazo_ubereats_dias,IF($D34="99Food",$A34+prazo_99food_dias,IF($E34="Débito",$A34+prazo_debito_dias,IF(OR($E34="Crédito à vista",$E34="Crédito parcelado"),$A34+prazo_credito_dias,$A34))))))) | J34: =IF($A34="","",IF($K34="Sim","Realizado",IF($I34<=TODAY(),"A Confirmar","Previsto"))) | K34: Sim | L34: Marcos (gerente) | N34: Taxas bancárias
A35: ◆ Limite da versão demonstrativa atingido (30 lançamentos). Versão completa: 3.000 lançamentos, contas a pagar/receber e relatório sem marca d'água.

Sheet CONTAS A PAGAR-RECEBER
A1: W.D.S. — CONTAS A PAGAR / RECEBER
A2: Ir para: | B2: INÍCIO | C2: CONFIG | D2: LANÇAMENTOS | E2: FLUXO DE CAIXA | F2: DASHBOARD | G2: RELATÓRIO | H2: DÚVIDAS
A3: ◆ Recurso disponível na versão completa. Nesta versão demonstrativa a aba fica visível para você ver como funciona, mas não aceita lançamentos.
A4: Descrição | B4: Tipo | C4: Fornecedor/Cliente | D4: Vencimento | E4: Valor (R$) | F4: Pago | G4: Status | H4: Observação | J4: chave de ordenação (uso interno)
G5: =IF($A5="","",IF($F5="Sim","Pago",IF($D5<TODAY(),"Atrasado","Pendente"))) | J5: =IF($A5="","",IF($F5="Sim","",IF($D5>TODAY()+30,"",$D5+ROW()/1000000)))
G6: =IF($A6="","",IF($F6="Sim","Pago",IF($D6<TODAY(),"Atrasado","Pendente"))) | J6: =IF($A6="","",IF($F6="Sim","",IF($D6>TODAY()+30,"",$D6+ROW()/1000000)))
G7: =IF($A7="","",IF($F7="Sim","Pago",IF($D7<TODAY(),"Atrasado","Pendente"))) | J7: =IF($A7="","",IF($F7="Sim","",IF($D7>TODAY()+30,"",$D7+ROW()/1000000)))
G8: =IF($A8="","",IF($F8="Sim","Pago",IF($D8<TODAY(),"Atrasado","Pendente"))) | J8: =IF($A8="","",IF($F8="Sim","",IF($D8>TODAY()+30,"",$D8+ROW()/1000000)))
G9: =IF($A9="","",IF($F9="Sim","Pago",IF($D9<TODAY(),"Atrasado","Pendente"))) | J9: =IF($A9="","",IF($F9="Sim","",IF($D9>TODAY()+30,"",$D9+ROW()/1000000)))
G10: =IF($A10="","",IF($F10="Sim","Pago",IF($D10<TODAY(),"Atrasado","Pendente"))) | J10: =IF($A10="","",IF($F10="Sim","",IF($D10>TODAY()+30,"",$D10+ROW()/1000000)))
G11: =IF($A11="","",IF($F11="Sim","Pago",IF($D11<TODAY(),"Atrasado","Pendente"))) | J11: =IF($A11="","",IF($F11="Sim","",IF($D11>TODAY()+30,"",$D11+ROW()/1000000)))
G12: =IF($A12="","",IF($F12="Sim","Pago",IF($D12<TODAY(),"Atrasado","Pendente"))) | J12: =IF($A12="","",IF($F12="Sim","",IF($D12>TODAY()+30,"",$D12+ROW()/1000000)))
G13: =IF($A13="","",IF($F13="Sim","Pago",IF($D13<TODAY(),"Atrasado","Pendente"))) | J13: =IF($A13="","",IF($F13="Sim","",IF($D13>TODAY()+30,"",$D13+ROW()/1000000)))
G14: =IF($A14="","",IF($F14="Sim","Pago",IF($D14<TODAY(),"Atrasado","Pendente"))) | J14: =IF($A14="","",IF($F14="Sim","",IF($D14>TODAY()+30,"",$D14+ROW()/1000000)))
G15: =IF($A15="","",IF($F15="Sim","Pago",IF($D15<TODAY(),"Atrasado","Pendente"))) | J15: =IF($A15="","",IF($F15="Sim","",IF($D15>TODAY()+30,"",$D15+ROW()/1000000)))
G16: =IF($A16="","",IF($F16="Sim","Pago",IF($D16<TODAY(),"Atrasado","Pendente"))) | J16: =IF($A16="","",IF($F16="Sim","",IF($D16>TODAY()+30,"",$D16+ROW()/1000000)))
... G24: =IF($A24="","",IF($F24="Sim","Pago",IF($D24<TODAY(),"Atrasado","Pendente"))) | J24: =IF($A24="","",IF($F24="Sim","",IF($D24>TODAY()+30,"",$D24+ROW()/1000000)))

Sheet FLUXO DE CAIXA
A1: W.D.S. — FLUXO DE CAIXA — PREVISTO x REALIZADO
A2: Ir para: | B2: INÍCIO | C2: CONFIG | D2: LANÇAMENTOS | E2: CONTAS A PAGAR-RECEBER | F2: DASHBOARD | G2: RELATÓRIO | H2: DÚVIDAS
A3: Calculado automaticamente a partir de LANÇAMENTOS. Previsto = tudo esperado no mês. Realizado depende do Modo de Apuração escolhido em CONFIG. Nada aqui é editável.
A5: Mês | B5: Entradas Previsto | C5: Entradas Realizado | D5: Saídas Previsto | E5: Saídas Realizado | F5: Saldo do Mês | G5: Saldo Acumulado
A6: =IFERROR(DATE(ano_referencia,1,1),"") | B6: =IFERROR(SUMIFS('LANÇAMENTOS'!$H$5:$H$34,'LANÇAMENTOS'!$B$5:$B$34,"Entrada",'LANÇAMENTOS'!$I$5:$I$34,">="&$A6,'LANÇAMENTOS'!$I$5:$I$34,"<="&EOMONTH($A6,0)),0) | C6: =IFERROR(IF(modo_apuracao="Conferencia",SUMIFS('LANÇAMENTOS'!$H$5:$H$34,'LANÇAMENTOS'!$B$5:$B$34,"Entrada",'LANÇAMENTOS'!$K$5:$K$34,"Sim",'LANÇAMENTOS'!$I$5:$I$34,">="&$A6,'LANÇAMENTOS'!$I$5:$I$34,"<="&EOMONTH($A6,0)),SUMIFS('LANÇAMENTOS'!$H$5:$H$34,'LANÇAMENTOS'!$B$5:$B$34,"Entrada",'LANÇAMENTOS'!$I$5:$I$34,"<="&TODAY(),'LANÇAMENTOS'!$I$5:$I$34,">="&$A6,'LANÇAMENTOS'!$I$5:$I$34,"<="&EOMONTH($A6,0))),0) | D6: =IFERROR(SUMIFS('LANÇAMENTOS'!$H$5:$H$34,'LANÇAMENTOS'!$B$5:$B$34,"Saída",'LANÇAMENTOS'!$I$5:$I$34,">="&$A6,'LANÇAMENTOS'!$I$5:$I$34,"<="&EOMONTH($A6,0)),0) | E6: =IFERROR(IF(modo_apuracao="Conferencia",SUMIFS('LANÇAMENTOS'!$H$5:$H$34,'LANÇAMENTOS'!$B$5:$B$34,"Saída",'LANÇAMENTOS'!$K$5:$K$34,"Sim",'LANÇAMENTOS'!$I$5:$I$34,">="&$A6,'LANÇAMENTOS'!$I$5:$I$34,"<="&EOMONTH($A6,0)),SUMIFS('LANÇAMENTOS'!$H$5:$H$34,'LANÇAMENTOS'!$B$5:$B$34,"Saída",'LANÇAMENTOS'!$I$5:$I$34,"<="&TODAY(),'LANÇAMENTOS'!$I$5:$I$34,">="&$A6,'LANÇAMENTOS'!$I$5:$I$34,"<="&EOMONTH($A6,0))),0) | F6: =$C6-$E6 | G6: =saldo_inicial+$F6
A7: =IFERROR(DATE(ano_referencia,2,1),"") | B7: =IFERROR(SUMIFS('LANÇAMENTOS'!$H$5:$H$34,'LANÇAMENTOS'!$B$5:$B$34,"Entrada",'LANÇAMENTOS'!$I$5:$I$34,">="&$A7,'LANÇAMENTOS'!$I$5:$I$34,"<="&EOMONTH($A7,0)),0) | C7: =IFERROR(IF(modo_apuracao="Conferencia",SUMIFS('LANÇAMENTOS'!$H$5:$H$34,'LANÇAMENTOS'!$B$5:$B$34,"Entrada",'LANÇAMENTOS'!$K$5:$K$34,"Sim",'LANÇAMENTOS'!$I$5:$I$34,">="&$A7,'LANÇAMENTOS'!$I$5:$I$34,"<="&EOMONTH($A7,0)),SUMIFS('LANÇAMENTOS'!$H$5:$H$34,'LANÇAMENTOS'!$B$5:$B$34,"Entrada",'LANÇAMENTOS'!$I$5:$I$34,"<="&TODAY(),'LANÇAMENTOS'!$I$5:$I$34,">="&$A7,'LANÇAMENTOS'!$I$5:$I$34,"<="&EOMONTH($A7,0))),0) | D7: =IFERROR(SUMIFS('LANÇAMENTOS'!$H$5:$H$34,'LANÇAMENTOS'!$B$5:$B$34,"Saída",'LANÇAMENTOS'!$I$5:$I$34,">="&$A7,'LANÇAMENTOS'!$I$5:$I$34,"<="&EOMONTH($A7,0)),0) | E7: =IFERROR(IF(modo_apuracao="Conferencia",SUMIFS('LANÇAMENTOS'!$H$5:$H$34,'LANÇAMENTOS'!$B$5:$B$34,"Saída",'LANÇAMENTOS'!$K$5:$K$34,"Sim",'LANÇAMENTOS'!$I$5:$I$34,">="&$A7,'LANÇAMENTOS'!$I$5:$I$34,"<="&EOMONTH($A7,0)),SUMIFS('LANÇAMENTOS'!$H$5:$H$34,'LANÇAMENTOS'!$B$5:$B$34,"Saída",'LANÇAMENTOS'!$I$5:$I$34,"<="&TODAY(),'LANÇAMENTOS'!$I$5:$I$34,">="&$A7,'LANÇAMENTOS'!$I$5:$I$34,"<="&EOMONTH($A7,0))),0) | F7: =$C7-$E7 | G7: =$G6+$F7
A8: =IFERROR(DATE(ano_referencia,3,1),"") | B8: =IFERROR(SUMIFS('LANÇAMENTOS'!$H$5:$H$34,'LANÇAMENTOS'!$B$5:$B$34,"Entrada",'LANÇAMENTOS'!$I$5:$I$34,">="&$A8,'LANÇAMENTOS'!$I$5:$I$34,"<="&EOMONTH($A8,0)),0) | C8: =IFERROR(IF(modo_apuracao="Conferencia",SUMIFS('LANÇAMENTOS'!$H$5:$H$34,'LANÇAMENTOS'!$B$5:$B$34,"Entrada",'LANÇAMENTOS'!$K$5:$K$34,"Sim",'LANÇAMENTOS'!$I$5:$I$34,">="&$A8,'LANÇAMENTOS'!$I$5:$I$34,"<="&EOMONTH($A8,0)),SUMIFS('LANÇAMENTOS'!$H$5:$H$34,'LANÇAMENTOS'!$B$5:$B$34,"Entrada",'LANÇAMENTOS'!$I$5:$I$34,"<="&TODAY(),'LANÇAMENTOS'!$I$5:$I$34,">="&$A8,'LANÇAMENTOS'!$I$5:$I$34,"<="&EOMONTH($A8,0))),0) | D8: =IFERROR(SUMIFS('LANÇAMENTOS'!$H$5:$H$34,'LANÇAMENTOS'!$B$5:$B$34,"Saída",'LANÇAMENTOS'!$I$5:$I$34,">="&$A8,'LANÇAMENTOS'!$I$5:$I$34,"<="&EOMONTH($A8,0)),0) | E8: =IFERROR(IF(modo_apuracao="Conferencia",SUMIFS('LANÇAMENTOS'!$H$5:$H$34,'LANÇAMENTOS'!$B$5:$B$34,"Saída",'LANÇAMENTOS'!$K$5:$K$34,"Sim",'LANÇAMENTOS'!$I$5:$I$34,">="&$A8,'LANÇAMENTOS'!$I$5:$I$34,"<="&EOMONTH($A8,0)),SUMIFS('LANÇAMENTOS'!$H$5:$H$34,'LANÇAMENTOS'!$B$5:$B$34,"Saída",'LANÇAMENTOS'!$I$5:$I$34,"<="&TODAY(),'LANÇAMENTOS'!$I$5:$I$34,">="&$A8,'LANÇAMENTOS'!$I$5:$I$34,"<="&EOMONTH($A8,0))),0) | F8: =$C8-$E8 | G8: =$G7+$F8
A9: =IFERROR(DATE(ano_referencia,4,1),"") | B9: =IFERROR(SUMIFS('LANÇAMENTOS'!$H$5:$H$34,'LANÇAMENTOS'!$B$5:$B$34,"Entrada",'LANÇAMENTOS'!$I$5:$I$34,">="&$A9,'LANÇAMENTOS'!$I$5:$I$34,"<="&EOMONTH($A9,0)),0) | C9: =IFERROR(IF(modo_apuracao="Conferencia",SUMIFS('LANÇAMENTOS'!$H$5:$H$34,'LANÇAMENTOS'!$B$5:$B$34,"Entrada",'LANÇAMENTOS'!$K$5:$K$34,"Sim",'LANÇAMENTOS'!$I$5:$I$34,">="&$A9,'LANÇAMENTOS'!$I$5:$I$34,"<="&EOMONTH($A9,0)),SUMIFS('LANÇAMENTOS'!$H$5:$H$34,'LANÇAMENTOS'!$B$5:$B$34,"Entrada",'LANÇAMENTOS'!$I$5:$I$34,"<="&TODAY(),'LANÇAMENTOS'!$I$5:$I$34,">="&$A9,'LANÇAMENTOS'!$I$5:$I$34,"<="&EOMONTH($A9,0))),0) | D9: =IFERROR(SUMIFS('LANÇAMENTOS'!$H$5:$H$34,'LANÇAMENTOS'!$B$5:$B$34,"Saída",'LANÇAMENTOS'!$I$5:$I$34,">="&$A9,'LANÇAMENTOS'!$I$5:$I$34,"<="&EOMONTH($A9,0)),0) | E9: =IFERROR(IF(modo_apuracao="Conferencia",SUMIFS('LANÇAMENTOS'!$H$5:$H$34,'LANÇAMENTOS'!$B$5:$B$34,"Saída",'LANÇAMENTOS'!$K$5:$K$34,"Sim",'LANÇAMENTOS'!$I$5:$I$34,">="&$A9,'LANÇAMENTOS'!$I$5:$I$34,"<="&EOMONTH($A9,0)),SUMIFS('LANÇAMENTOS'!$H$5:$H$34,'LANÇAMENTOS'!$B$5:$B$34,"Saída",'LANÇAMENTOS'!$I$5:$I$34,"<="&TODAY(),'LANÇAMENTOS'!$I$5:$I$34,">="&$A9,'LANÇAMENTOS'!$I$5:$I$34,"<="&EOMONTH($A9,0))),0) | F9: =$C9-$E9 | G9: =$G8+$F9
A10: =IFERROR(DATE(ano_referencia,5,1),"") | B10: =IFERROR(SUMIFS('LANÇAMENTOS'!$H$5:$H$34,'LANÇAMENTOS'!$B$5:$B$34,"Entrada",'LANÇAMENTOS'!$I$5:$I$34,">="&$A10,'LANÇAMENTOS'!$I$5:$I$34,"<="&EOMONTH($A10,0)),0) | C10: =IFERROR(IF(modo_apuracao="Conferencia",SUMIFS('LANÇAMENTOS'!$H$5:$H$34,'LANÇAMENTOS'!$B$5:$B$34,"Entrada",'LANÇAMENTOS'!$K$5:$K$34,"Sim",'LANÇAMENTOS'!$I$5:$I$34,">="&$A10,'LANÇAMENTOS'!$I$5:$I$34,"<="&EOMONTH($A10,0)),SUMIFS('LANÇAMENTOS'!$H$5:$H$34,'LANÇAMENTOS'!$B$5:$B$34,"Entrada",'LANÇAMENTOS'!$I$5:$I$34,"<="&TODAY(),'LANÇAMENTOS'!$I$5:$I$34,">="&$A10,'LANÇAMENTOS'!$I$5:$I$34,"<="&EOMONTH($A10,0))),0) | D10: =IFERROR(SUMIFS('LANÇAMENTOS'!$H$5:$H$34,'LANÇAMENTOS'!$B$5:$B$34,"Saída",'LANÇAMENTOS'!$I$5:$I$34,">="&$A10,'LANÇAMENTOS'!$I$5:$I$34,"<="&EOMONTH($A10,0)),0) | E10: =IFERROR(IF(modo_apuracao="Conferencia",SUMIFS('LANÇAMENTOS'!$H$5:$H$34,'LANÇAMENTOS'!$B$5:$B$34,"Saída",'LANÇAMENTOS'!$K$5:$K$34,"Sim",'LANÇAMENTOS'!$I$5:$I$34,">="&$A10,'LANÇAMENTOS'!$I$5:$I$34,"<="&EOMONTH($A10,0)),SUMIFS('LANÇAMENTOS'!$H$5:$H$34,'LANÇAMENTOS'!$B$5:$B$34,"Saída",'LANÇAMENTOS'!$I$5:$I$34,"<="&TODAY(),'LANÇAMENTOS'!$I$5:$I$34,">="&$A10,'LANÇAMENTOS'!$I$5:$I$34,"<="&EOMONTH($A10,0))),0) | F10: =$C10-$E10 | G10: =$G9+$F10
A11: =IFERROR(DATE(ano_referencia,6,1),"") | B11: =IFERROR(SUMIFS('LANÇAMENTOS'!$H$5:$H$34,'LANÇAMENTOS'!$B$5:$B$34,"Entrada",'LANÇAMENTOS'!$I$5:$I$34,">="&$A11,'LANÇAMENTOS'!$I$5:$I$34,"<="&EOMONTH($A11,0)),0) | C11: =IFERROR(IF(modo_apuracao="Conferencia",SUMIFS('LANÇAMENTOS'!$H$5:$H$34,'LANÇAMENTOS'!$B$5:$B$34,"Entrada",'LANÇAMENTOS'!$K$5:$K$34,"Sim",'LANÇAMENTOS'!$I$5:$I$34,">="&$A11,'LANÇAMENTOS'!$I$5:$I$34,"<="&EOMONTH($A11,0)),SUMIFS('LANÇAMENTOS'!$H$5:$H$34,'LANÇAMENTOS'!$B$5:$B$34,"Entrada",'LANÇAMENTOS'!$I$5:$I$34,"<="&TODAY(),'LANÇAMENTOS'!$I$5:$I$34,">="&$A11,'LANÇAMENTOS'!$I$5:$I$34,"<="&EOMONTH($A11,0))),0) | D11: =IFERROR(SUMIFS('LANÇAMENTOS'!$H$5:$H$34,'LANÇAMENTOS'!$B$5:$B$34,"Saída",'LANÇAMENTOS'!$I$5:$I$34,">="&$A11,'LANÇAMENTOS'!$I$5:$I$34,"<="&EOMONTH($A11,0)),0) | E11: =IFERROR(IF(modo_apuracao="Conferencia",SUMIFS('LANÇAMENTOS'!$H$5:$H$34,'LANÇAMENTOS'!$B$5:$B$34,"Saída",'LANÇAMENTOS'!$K$5:$K$34,"Sim",'LANÇAMENTOS'!$I$5:$I$34,">="&$A11,'LANÇAMENTOS'!$I$5:$I$34,"<="&EOMONTH($A11,0)),SUMIFS('LANÇAMENTOS'!$H$5:$H$34,'LANÇAMENTOS'!$B$5:$B$34,"Saída",'LANÇAMENTOS'!$I$5:$I$34,"<="&TODAY(),'LANÇAMENTOS'!$I$5:$I$34,">="&$A11,'LANÇAMENTOS'!$I$5:$I$34,"<="&EOMONTH($A11,0))),0) | F11: =$C11-$E11 | G11: =$G10+$F11
A12: =IFERROR(DATE(ano_referencia,7,1),"") | B12: =IFERROR(SUMIFS('LANÇAMENTOS'!$H$5:$H$34,'LANÇAMENTOS'!$B$5:$B$34,"Entrada",'LANÇAMENTOS'!$I$5:$I$34,">="&$A12,'LANÇAMENTOS'!$I$5:$I$34,"<="&EOMONTH($A12,0)),0) | C12: =IFERROR(IF(modo_apuracao="Conferencia",SUMIFS('LANÇAMENTOS'!$H$5:$H$34,'LANÇAMENTOS'!$B$5:$B$34,"Entrada",'LANÇAMENTOS'!$K$5:$K$34,"Sim",'LANÇAMENTOS'!$I$5:$I$34,">="&$A12,'LANÇAMENTOS'!$I$5:$I$34,"<="&EOMONTH($A12,0)),SUMIFS('LANÇAMENTOS'!$H$5:$H$34,'LANÇAMENTOS'!$B$5:$B$34,"Entrada",'LANÇAMENTOS'!$I$5:$I$34,"<="&TODAY(),'LANÇAMENTOS'!$I$5:$I$34,">="&$A12,'LANÇAMENTOS'!$I$5:$I$34,"<="&EOMONTH($A12,0))),0) | D12: =IFERROR(SUMIFS('LANÇAMENTOS'!$H$5:$H$34,'LANÇAMENTOS'!$B$5:$B$34,"Saída",'LANÇAMENTOS'!$I$5:$I$34,">="&$A12,'LANÇAMENTOS'!$I$5:$I$34,"<="&EOMONTH($A12,0)),0) | E12: =IFERROR(IF(modo_apuracao="Conferencia",SUMIFS('LANÇAMENTOS'!$H$5:$H$34,'LANÇAMENTOS'!$B$5:$B$34,"Saída",'LANÇAMENTOS'!$K$5:$K$34,"Sim",'LANÇAMENTOS'!$I$5:$I$34,">="&$A12,'LANÇAMENTOS'!$I$5:$I$34,"<="&EOMONTH($A12,0)),SUMIFS('LANÇAMENTOS'!$H$5:$H$34,'LANÇAMENTOS'!$B$5:$B$34,"Saída",'LANÇAMENTOS'!$I$5:$I$34,"<="&TODAY(),'LANÇAMENTOS'!$I$5:$I$34,">="&$A12,'LANÇAMENTOS'!$I$5:$I$34,"<="&EOMONTH($A12,0))),0) | F12: =$C12-$E12 | G12: =$G11+$F12
A13: =IFERROR(DATE(ano_referencia,8,1),"") | B13: =IFERROR(SUMIFS('LANÇAMENTOS'!$H$5:$H$34,'LANÇAMENTOS'!$B$5:$B$34,"Entrada",'LANÇAMENTOS'!$I$5:$I$34,">="&$A13,'LANÇAMENTOS'!$I$5:$I$34,"<="&EOMONTH($A13,0)),0) | C13: =IFERROR(IF(modo_apuracao="Conferencia",SUMIFS('LANÇAMENTOS'!$H$5:$H$34,'LANÇAMENTOS'!$B$5:$B$34,"Entrada",'LANÇAMENTOS'!$K$5:$K$34,"Sim",'LANÇAMENTOS'!$I$5:$I$34,">="&$A13,'LANÇAMENTOS'!$I$5:$I$34,"<="&EOMONTH($A13,0)),SUMIFS('LANÇAMENTOS'!$H$5:$H$34,'LANÇAMENTOS'!$B$5:$B$34,"Entrada",'LANÇAMENTOS'!$I$5:$I$34,"<="&TODAY(),'LANÇAMENTOS'!$I$5:$I$34,">="&$A13,'LANÇAMENTOS'!$I$5:$I$34,"<="&EOMONTH($A13,0))),0) | D13: =IFERROR(SUMIFS('LANÇAMENTOS'!$H$5:$H$34,'LANÇAMENTOS'!$B$5:$B$34,"Saída",'LANÇAMENTOS'!$I$5:$I$34,">="&$A13,'LANÇAMENTOS'!$I$5:$I$34,"<="&EOMONTH($A13,0)),0) | E13: =IFERROR(IF(modo_apuracao="Conferencia",SUMIFS('LANÇAMENTOS'!$H$5:$H$34,'LANÇAMENTOS'!$B$5:$B$34,"Saída",'LANÇAMENTOS'!$K$5:$K$34,"Sim",'LANÇAMENTOS'!$I$5:$I$34,">="&$A13,'LANÇAMENTOS'!$I$5:$I$34,"<="&EOMONTH($A13,0)),SUMIFS('LANÇAMENTOS'!$H$5:$H$34,'LANÇAMENTOS'!$B$5:$B$34,"Saída",'LANÇAMENTOS'!$I$5:$I$34,"<="&TODAY(),'LANÇAMENTOS'!$I$5:$I$34,">="&$A13,'LANÇAMENTOS'!$I$5:$I$34,"<="&EOMONTH($A13,0))),0) | F13: =$C13-$E13 | G13: =$G12+$F13
A14: =IFERROR(DATE(ano_referencia,9,1),"") | B14: =IFERROR(SUMIFS('LANÇAMENTOS'!$H$5:$H$34,'LANÇAMENTOS'!$B$5:$B$34,"Entrada",'LANÇAMENTOS'!$I$5:$I$34,">="&$A14,'LANÇAMENTOS'!$I$5:$I$34,"<="&EOMONTH($A14,0)),0) | C14: =IFERROR(IF(modo_apuracao="Conferencia",SUMIFS('LANÇAMENTOS'!$H$5:$H$34,'LANÇAMENTOS'!$B$5:$B$34,"Entrada",'LANÇAMENTOS'!$K$5:$K$34,"Sim",'LANÇAMENTOS'!$I$5:$I$34,">="&$A14,'LANÇAMENTOS'!$I$5:$I$34,"<="&EOMONTH($A14,0)),SUMIFS('LANÇAMENTOS'!$H$5:$H$34,'LANÇAMENTOS'!$B$5:$B$34,"Entrada",'LANÇAMENTOS'!$I$5:$I$34,"<="&TODAY(),'LANÇAMENTOS'!$I$5:$I$34,">="&$A14,'LANÇAMENTOS'!$I$5:$I$34,"<="&EOMONTH($A14,0))),0) | D14: =IFERROR(SUMIFS('LANÇAMENTOS'!$H$5:$H$34,'LANÇAMENTOS'!$B$5:$B$34,"Saída",'LANÇAMENTOS'!$I$5:$I$34,">="&$A14,'LANÇAMENTOS'!$I$5:$I$34,"<="&EOMONTH($A14,0)),0) | E14: =IFERROR(IF(modo_apuracao="Conferencia",SUMIFS('LANÇAMENTOS'!$H$5:$H$34,'LANÇAMENTOS'!$B$5:$B$34,"Saída",'LANÇAMENTOS'!$K$5:$K$34,"Sim",'LANÇAMENTOS'!$I$5:$I$34,">="&$A14,'LANÇAMENTOS'!$I$5:$I$34,"<="&EOMONTH($A14,0)),SUMIFS('LANÇAMENTOS'!$H$5:$H$34,'LANÇAMENTOS'!$B$5:$B$34,"Saída",'LANÇAMENTOS'!$I$5:$I$34,"<="&TODAY(),'LANÇAMENTOS'!$I$5:$I$34,">="&$A14,'LANÇAMENTOS'!$I$5:$I$34,"<="&EOMONTH($A14,0))),0) | F14: =$C14-$E14 | G14: =$G13+$F14
A15: =IFERROR(DATE(ano_referencia,10,1),"") | B15: =IFERROR(SUMIFS('LANÇAMENTOS'!$H$5:$H$34,'LANÇAMENTOS'!$B$5:$B$34,"Entrada",'LANÇAMENTOS'!$I$5:$I$34,">="&$A15,'LANÇAMENTOS'!$I$5:$I$34,"<="&EOMONTH($A15,0)),0) | C15: =IFERROR(IF(modo_apuracao="Conferencia",SUMIFS('LANÇAMENTOS'!$H$5:$H$34,'LANÇAMENTOS'!$B$5:$B$34,"Entrada",'LANÇAMENTOS'!$K$5:$K$34,"Sim",'LANÇAMENTOS'!$I$5:$I$34,">="&$A15,'LANÇAMENTOS'!$I$5:$I$34,"<="&EOMONTH($A15,0)),SUMIFS('LANÇAMENTOS'!$H$5:$H$34,'LANÇAMENTOS'!$B$5:$B$34,"Entrada",'LANÇAMENTOS'!$I$5:$I$34,"<="&TODAY(),'LANÇAMENTOS'!$I$5:$I$34,">="&$A15,'LANÇAMENTOS'!$I$5:$I$34,"<="&EOMONTH($A15,0))),0) | D15: =IFERROR(SUMIFS('LANÇAMENTOS'!$H$5:$H$34,'LANÇAMENTOS'!$B$5:$B$34,"Saída",'LANÇAMENTOS'!$I$5:$I$34,">="&$A15,'LANÇAMENTOS'!$I$5:$I$34,"<="&EOMONTH($A15,0)),0) | E15: =IFERROR(IF(modo_apuracao="Conferencia",SUMIFS('LANÇAMENTOS'!$H$5:$H$34,'LANÇAMENTOS'!$B$5:$B$34,"Saída",'LANÇAMENTOS'!$K$5:$K$34,"Sim",'LANÇAMENTOS'!$I$5:$I$34,">="&$A15,'LANÇAMENTOS'!$I$5:$I$34,"<="&EOMONTH($A15,0)),SUMIFS('LANÇAMENTOS'!$H$5:$H$34,'LANÇAMENTOS'!$B$5:$B$34,"Saída",'LANÇAMENTOS'!$I$5:$I$34,"<="&TODAY(),'LANÇAMENTOS'!$I$5:$I$34,">="&$A15,'LANÇAMENTOS'!$I$5:$I$34,"<="&EOMONTH($A15,0))),0) | F15: =$C15-$E15 | G15: =$G14+$F15
A16: =IFERROR(DATE(ano_referencia,11,1),"") | B16: =IFERROR(SUMIFS('LANÇAMENTOS'!$H$5:$H$34,'LANÇAMENTOS'!$B$5:$B$34,"Entrada",'LANÇAMENTOS'!$I$5:$I$34,">="&$A16,'LANÇAMENTOS'!$I$5:$I$34,"<="&EOMONTH($A16,0)),0) | C16: =IFERROR(IF(modo_apuracao="Conferencia",SUMIFS('LANÇAMENTOS'!$H$5:$H$34,'LANÇAMENTOS'!$B$5:$B$34,"Entrada",'LANÇAMENTOS'!$K$5:$K$34,"Sim",'LANÇAMENTOS'!$I$5:$I$34,">="&$A16,'LANÇAMENTOS'!$I$5:$I$34,"<="&EOMONTH($A16,0)),SUMIFS('LANÇAMENTOS'!$H$5:$H$34,'LANÇAMENTOS'!$B$5:$B$34,"Entrada",'LANÇAMENTOS'!$I$5:$I$34,"<="&TODAY(),'LANÇAMENTOS'!$I$5:$I$34,">="&$A16,'LANÇAMENTOS'!$I$5:$I$34,"<="&EOMONTH($A16,0))),0) | D16: =IFERROR(SUMIFS('LANÇAMENTOS'!$H$5:$H$34,'LANÇAMENTOS'!$B$5:$B$34,"Saída",'LANÇAMENTOS'!$I$5:$I$34,">="&$A16,'LANÇAMENTOS'!$I$5:$I$34,"<="&EOMONTH($A16,0)),0) | E16: =IFERROR(IF(modo_apuracao="Conferencia",SUMIFS('LANÇAMENTOS'!$H$5:$H$34,'LANÇAMENTOS'!$B$5:$B$34,"Saída",'LANÇAMENTOS'!$K$5:$K$34,"Sim",'LANÇAMENTOS'!$I$5:$I$34,">="&$A16,'LANÇAMENTOS'!$I$5:$I$34,"<="&EOMONTH($A16,0)),SUMIFS('LANÇAMENTOS'!$H$5:$H$34,'LANÇAMENTOS'!$B$5:$B$34,"Saída",'LANÇAMENTOS'!$I$5:$I$34,"<="&TODAY(),'LANÇAMENTOS'!$I$5:$I$34,">="&$A16,'LANÇAMENTOS'!$I$5:$I$34,"<="&EOMONTH($A16,0))),0) | F16: =$C16-$E16 | G16: =$G15+$F16
A17: =IFERROR(DATE(ano_referencia,12,1),"") | B17: =IFERROR(SUMIFS('LANÇAMENTOS'!$H$5:$H$34,'LANÇAMENTOS'!$B$5:$B$34,"Entrada",'LANÇAMENTOS'!$I$5:$I$34,">="&$A17,'LANÇAMENTOS'!$I$5:$I$34,"<="&EOMONTH($A17,0)),0) | C17: =IFERROR(IF(modo_apuracao="Conferencia",SUMIFS('LANÇAMENTOS'!$H$5:$H$34,'LANÇAMENTOS'!$B$5:$B$34,"Entrada",'LANÇAMENTOS'!$K$5:$K$34,"Sim",'LANÇAMENTOS'!$I$5:$I$34,">="&$A17,'LANÇAMENTOS'!$I$5:$I$34,"<="&EOMONTH($A17,0)),SUMIFS('LANÇAMENTOS'!$H$5:$H$34,'LANÇAMENTOS'!$B$5:$B$34,"Entrada",'LANÇAMENTOS'!$I$5:$I$34,"<="&TODAY(),'LANÇAMENTOS'!$I$5:$I$34,">="&$A17,'LANÇAMENTOS'!$I$5:$I$34,"<="&EOMONTH($A17,0))),0) | D17: =IFERROR(SUMIFS('LANÇAMENTOS'!$H$5:$H$34,'LANÇAMENTOS'!$B$5:$B$34,"Saída",'LANÇAMENTOS'!$I$5:$I$34,">="&$A17,'LANÇAMENTOS'!$I$5:$I$34,"<="&EOMONTH($A17,0)),0) | E17: =IFERROR(IF(modo_apuracao="Conferencia",SUMIFS('LANÇAMENTOS'!$H$5:$H$34,'LANÇAMENTOS'!$B$5:$B$34,"Saída",'LANÇAMENTOS'!$K$5:$K$34,"Sim",'LANÇAMENTOS'!$I$5:$I$34,">="&$A17,'LANÇAMENTOS'!$I$5:$I$34,"<="&EOMONTH($A17,0)),SUMIFS('LANÇAMENTOS'!$H$5:$H$34,'LANÇAMENTOS'!$B$5:$B$34,"Saída",'LANÇAMENTOS'!$I$5:$I$34,"<="&TODAY(),'LANÇAMENTOS'!$I$5:$I$34,">="&$A17,'LANÇAMENTOS'!$I$5:$I$34,"<="&EOMONTH($A17,0))),0) | F17: =$C17-$E17 | G17: =$G16+$F17
A20: DETALHAMENTO POR CATEGORIA
A21: Mês selecionado: | B21: 46023
A23: Categoria | B23: Entradas Previsto | C23: Entradas Realizado | D23: Saídas Previsto | E23: Saídas Realizado
A24: ='CONFIG'!$B$27 | B24: =IF($A24="","",IFERROR(SUMIFS('LANÇAMENTOS'!$H$5:$H$34,'LANÇAMENTOS'!$B$5:$B$34,"Entrada",'LANÇAMENTOS'!$C$5:$C$34,$A24,'LANÇAMENTOS'!$I$5:$I$34,">="&$B$21,'LANÇAMENTOS'!$I$5:$I$34,"<="&EOMONTH($B$21,0)),0)) | C24: =IF($A24="","",IFERROR(IF(modo_apuracao="Conferencia",SUMIFS('LANÇAMENTOS'!$H$5:$H$34,'LANÇAMENTOS'!$B$5:$B$34,"Entrada",'LANÇAMENTOS'!$C$5:$C$34,$A24,'LANÇAMENTOS'!$K$5:$K$34,"Sim",'LANÇAMENTOS'!$I$5:$I$34,">="&$B$21,'LANÇAMENTOS'!$I$5:$I$34,"<="&EOMONTH($B$21,0)),SUMIFS('LANÇAMENTOS'!$H$5:$H$34,'LANÇAMENTOS'!$B$5:$B$34,"Entrada",'LANÇAMENTOS'!$C$5:$C$34,$A24,'LANÇAMENTOS'!$I$5:$I$34,"<="&TODAY(),'LANÇAMENTOS'!$I$5:$I$34,">="&$B$21,'LANÇAMENTOS'!$I$5:$I$34,"<="&EOMONTH($B$21,0))),0)) | D24: =IF($A24="","",IFERROR(SUMIFS('LANÇAMENTOS'!$H$5:$H$34,'LANÇAMENTOS'!$B$5:$B$34,"Saída",'LANÇAMENTOS'!$C$5:$C$34,$A24,'LANÇAMENTOS'!$I$5:$I$34,">="&$B$21,'LANÇAMENTOS'!$I$5:$I$34,"<="&EOMONTH($B$21,0)),0)) | E24: =IF($A24="","",IFERROR(IF(modo_apuracao="Conferencia",SUMIFS('LANÇAMENTOS'!$H$5:$H$34,'LANÇAMENTOS'!$B$5:$B$34,"Saída",'LANÇAMENTOS'!$C$5:$C$34,$A24,'LANÇAMENTOS'!$K$5:$K$34,"Sim",'LANÇAMENTOS'!$I$5:$I$34,">="&$B$21,'LANÇAMENTOS'!$I$5:$I$34,"<="&EOMONTH($B$21,0)),SUMIFS('LANÇAMENTOS'!$H$5:$H$34,'LANÇAMENTOS'!$B$5:$B$34,"Saída",'LANÇAMENTOS'!$C$5:$C$34,$A24,'LANÇAMENTOS'!$I$5:$I$34,"<="&TODAY(),'LANÇAMENTOS'!$I$5:$I$34,">="&$B$21,'LANÇAMENTOS'!$I$5:$I$34,"<="&EOMONTH($B$21,0))),0))
A25: ='CONFIG'!$B$28 | B25: =IF($A25="","",IFERROR(SUMIFS('LANÇAMENTOS'!$H$5:$H$34,'LANÇAMENTOS'!$B$5:$B$34,"Entrada",'LANÇAMENTOS'!$C$5:$C$34,$A25,'LANÇAMENTOS'!$I$5:$I$34,">="&$B$21,'LANÇAMENTOS'!$I$5:$I$34,"<="&EOMONTH($B$21,0)),0)) | C25: =IF($A25="","",IFERROR(IF(modo_apuracao="Conferencia",SUMIFS('LANÇAMENTOS'!$H$5:$H$34,'LANÇAMENTOS'!$B$5:$B$34,"Entrada",'LANÇAMENTOS'!$C$5:$C$34,$A25,'LANÇAMENTOS'!$K$5:$K$34,"Sim",'LANÇAMENTOS'!$I$5:$I$34,">="&$B$21,'LANÇAMENTOS'!$I$5:$I$34,"<="&EOMONTH($B$21,0)),SUMIFS('LANÇAMENTOS'!$H$5:$H$34,'LANÇAMENTOS'!$B$5:$B$34,"Entrada",'LANÇAMENTOS'!$C$5:$C$34,$A25,'LANÇAMENTOS'!$I$5:$I$34,"<="&TODAY(),'LANÇAMENTOS'!$I$5:$I$34,">="&$B$21,'LANÇAMENTOS'!$I$5:$I$34,"<="&EOMONTH($B$21,0))),0)) | D25: =IF($A25="","",IFERROR(SUMIFS('LANÇAMENTOS'!$H$5:$H$34,'LANÇAMENTOS'!$B$5:$B$34,"Saída",'LANÇAMENTOS'!$C$5:$C$34,$A25,'LANÇAMENTOS'!$I$5:$I$34,">="&$B$21,'LANÇAMENTOS'!$I$5:$I$34,"<="&EOMONTH($B$21,0)),0)) | E25: =IF($A25="","",IFERROR(IF(modo_apuracao="Conferencia",SUMIFS('LANÇAMENTOS'!$H$5:$H$34,'LANÇAMENTOS'!$B$5:$B$34,"Saída",'LANÇAMENTOS'!$C$5:$C$34,$A25,'LANÇAMENTOS'!$K$5:$K$34,"Sim",'LANÇAMENTOS'!$I$5:$I$34,">="&$B$21,'LANÇAMENTOS'!$I$5:$I$34,"<="&EOMONTH($B$21,0)),SUMIFS('LANÇAMENTOS'!$H$5:$H$34,'LANÇAMENTOS'!$B$5:$B$34,"Saída",'LANÇAMENTOS'!$C$5:$C$34,$A25,'LANÇAMENTOS'!$I$5:$I$34,"<="&TODAY(),'LANÇAMENTOS'!$I$5:$I$34,">="&$B$21,'LANÇAMENTOS'!$I$5:$I$34,"<="&EOMONTH($B$21,0))),0))
A26: ='CONFIG'!$B$29 | B26: =IF($A26="","",IFERROR(SUMIFS('LANÇAMENTOS'!$H$5:$H$34,'LANÇAMENTOS'!$B$5:$B$34,"Entrada",'LANÇAMENTOS'!$C$5:$C$34,$A26,'LANÇAMENTOS'!$I$5:$I$34,">="&$B$21,'LANÇAMENTOS'!$I$5:$I$34,"<="&EOMONTH($B$21,0)),0)) | C26: =IF($A26="","",IFERROR(IF(modo_apuracao="Conferencia",SUMIFS('LANÇAMENTOS'!$H$5:$H$34,'LANÇAMENTOS'!$B$5:$B$34,"Entrada",'LANÇAMENTOS'!$C$5:$C$34,$A26,'LANÇAMENTOS'!$K$5:$K$34,"Sim",'LANÇAMENTOS'!$I$5:$I$34,">="&$B$21,'LANÇAMENTOS'!$I$5:$I$34,"<="&EOMONTH($B$21,0)),SUMIFS('LANÇAMENTOS'!$H$5:$H$34,'LANÇAMENTOS'!$B$5:$B$34,"Entrada",'LANÇAMENTOS'!$C$5:$C$34,$A26,'LANÇAMENTOS'!$I$5:$I$34,"<="&TODAY(),'LANÇAMENTOS'!$I$5:$I$34,">="&$B$21,'LANÇAMENTOS'!$I$5:$I$34,"<="&EOMONTH($B$21,0))),0)) | D26: =IF($A26="","",IFERROR(SUMIFS('LANÇAMENTOS'!$H$5:$H$34,'LANÇAMENTOS'!$B$5:$B$34,"Saída",'LANÇAMENTOS'!$C$5:$C$34,$A26,'LANÇAMENTOS'!$I$5:$I$34,">="&$B$21,'LANÇAMENTOS'!$I$5:$I$34,"<="&EOMONTH($B$21,0)),0)) | E26: =IF($A26="","",IFERROR(IF(modo_apuracao="Conferencia",SUMIFS('LANÇAMENTOS'!$H$5:$H$34,'LANÇAMENTOS'!$B$5:$B$34,"Saída",'LANÇAMENTOS'!$C$5:$C$34,$A26,'LANÇAMENTOS'!$K$5:$K$34,"Sim",'LANÇAMENTOS'!$I$5:$I$34,">="&$B$21,'LANÇAMENTOS'!$I$5:$I$34,"<="&EOMONTH($B$21,0)),SUMIFS('LANÇAMENTOS'!$H$5:$H$34,'LANÇAMENTOS'!$B$5:$B$34,"Saída",'LANÇAMENTOS'!$C$5:$C$34,$A26,'LANÇAMENTOS'!$I$5:$I$34,"<="&TODAY(),'LANÇAMENTOS'!$I$5:$I$34,">="&$B$21,'LANÇAMENTOS'!$I$5:$I$34,"<="&EOMONTH($B$21,0))),0))
A27: ='CONFIG'!$B$30 | B27: =IF($A27="","",IFERROR(SUMIFS('LANÇAMENTOS'!$H$5:$H$34,'LANÇAMENTOS'!$B$5:$B$34,"Entrada",'LANÇAMENTOS'!$C$5:$C$34,$A27,'LANÇAMENTOS'!$I$5:$I$34,">="&$B$21,'LANÇAMENTOS'!$I$5:$I$34,"<="&EOMONTH($B$21,0)),0)) | C27: =IF($A27="","",IFERROR(IF(modo_apuracao="Conferencia",SUMIFS('LANÇAMENTOS'!$H$5:$H$34,'LANÇAMENTOS'!$B$5:$B$34,"Entrada",'LANÇAMENTOS'!$C$5:$C$34,$A27,'LANÇAMENTOS'!$K$5:$K$34,"Sim",'LANÇAMENTOS'!$I$5:$I$34,">="&$B$21,'LANÇAMENTOS'!$I$5:$I$34,"<="&EOMONTH($B$21,0)),SUMIFS('LANÇAMENTOS'!$H$5:$H$34,'LANÇAMENTOS'!$B$5:$B$34,"Entrada",'LANÇAMENTOS'!$C$5:$C$34,$A27,'LANÇAMENTOS'!$I$5:$I$34,"<="&TODAY(),'LANÇAMENTOS'!$I$5:$I$34,">="&$B$21,'LANÇAMENTOS'!$I$5:$I$34,"<="&EOMONTH($B$21,0))),0)) | D27: =IF($A27="","",IFERROR(SUMIFS('LANÇAMENTOS'!$H$5:$H$34,'LANÇAMENTOS'!$B$5:$B$34,"Saída",'LANÇAMENTOS'!$C$5:$C$34,$A27,'LANÇAMENTOS'!$I$5:$I$34,">="&$B$21,'LANÇAMENTOS'!$I$5:$I$34,"<="&EOMONTH($B$21,0)),0)) | E27: =IF($A27="","",IFERROR(IF(modo_apuracao="Conferencia",SUMIFS('LANÇAMENTOS'!$H$5:$H$34,'LANÇAMENTOS'!$B$5:$B$34,"Saída",'LANÇAMENTOS'!$C$5:$C$34,$A27,'LANÇAMENTOS'!$K$5:$K$34,"Sim",'LANÇAMENTOS'!$I$5:$I$34,">="&$B$21,'LANÇAMENTOS'!$I$5:$I$34,"<="&EOMONTH($B$21,0)),SUMIFS('LANÇAMENTOS'!$H$5:$H$34,'LANÇAMENTOS'!$B$5:$B$34,"Saída",'LANÇAMENTOS'!$C$5:$C$34,$A27,'LANÇAMENTOS'!$I$5:$I$34,"<="&TODAY(),'LANÇAMENTOS'!$I$5:$I$34,">="&$B$21,'LANÇAMENTOS'!$I$5:$I$34,"<="&EOMONTH($B$21,0))),0))
A28: ='CONFIG'!$B$31 | B28: =IF($A28="","",IFERROR(SUMIFS('LANÇAMENTOS'!$H$5:$H$34,'LANÇAMENTOS'!$B$5:$B$34,"Entrada",'LANÇAMENTOS'!$C$5:$C$34,$A28,'LANÇAMENTOS'!$I$5:$I$34,">="&$B$21,'LANÇAMENTOS'!$I$5:$I$34,"<="&EOMONTH($B$21,0)),0)) | C28: =IF($A28="","",IFERROR(IF(modo_apuracao="Conferencia",SUMIFS('LANÇAMENTOS'!$H$5:$H$34,'LANÇAMENTOS'!$B$5:$B$34,"Entrada",'LANÇAMENTOS'!$C$5:$C$34,$A28,'LANÇAMENTOS'!$K$5:$K$34,"Sim",'LANÇAMENTOS'!$I$5:$I$34,">="&$B$21,'LANÇAMENTOS'!$I$5:$I$34,"<="&EOMONTH($B$21,0)),SUMIFS('LANÇAMENTOS'!$H$5:$H$34,'LANÇAMENTOS'!$B$5:$B$34,"Entrada",'LANÇAMENTOS'!$C$5:$C$34,$A28,'LANÇAMENTOS'!$I$5:$I$34,"<="&TODAY(),'LANÇAMENTOS'!$I$5:$I$34,">="&$B$21,'LANÇAMENTOS'!$I$5:$I$34,"<="&EOMONTH($B$21,0))),0)) | D28: =IF($A28="","",IFERROR(SUMIFS('LANÇAMENTOS'!$H$5:$H$34,'LANÇAMENTOS'!$B$5:$B$34,"Saída",'LANÇAMENTOS'!$C$5:$C$34,$A28,'LANÇAMENTOS'!$I$5:$I$34,">="&$B$21,'LANÇAMENTOS'!$I$5:$I$34,"<="&EOMONTH($B$21,0)),0)) | E28: =IF($A28="","",IFERROR(IF(modo_apuracao="Conferencia",SUMIFS('LANÇAMENTOS'!$H$5:$H$34,'LANÇAMENTOS'!$B$5:$B$34,"Saída",'LANÇAMENTOS'!$C$5:$C$34,$A28,'LANÇAMENTOS'!$K$5:$K$34,"Sim",'LANÇAMENTOS'!$I$5:$I$34,">="&$B$21,'LANÇAMENTOS'!$I$5:$I$34,"<="&EOMONTH($B$21,0)),SUMIFS('LANÇAMENTOS'!$H$5:$H$34,'LANÇAMENTOS'!$B$5:$B$34,"Saída",'LANÇAMENTOS'!$C$5:$C$34,$A28,'LANÇAMENTOS'!$I$5:$I$34,"<="&TODAY(),'LANÇAMENTOS'!$I$5:$I$34,">="&$B$21,'LANÇAMENTOS'!$I$5:$I$34,"<="&EOMONTH($B$21,0))),0))
A29: ='CONFIG'!$B$32 | B29: =IF($A29="","",IFERROR(SUMIFS('LANÇAMENTOS'!$H$5:$H$34,'LANÇAMENTOS'!$B$5:$B$34,"Entrada",'LANÇAMENTOS'!$C$5:$C$34,$A29,'LANÇAMENTOS'!$I$5:$I$34,">="&$B$21,'LANÇAMENTOS'!$I$5:$I$34,"<="&EOMONTH($B$21,0)),0)) | C29: =IF($A29="","",IFERROR(IF(modo_apuracao="Conferencia",SUMIFS('LANÇAMENTOS'!$H$5:$H$34,'LANÇAMENTOS'!$B$5:$B$34,"Entrada",'LANÇAMENTOS'!$C$5:$C$34,$A29,'LANÇAMENTOS'!$K$5:$K$34,"Sim",'LANÇAMENTOS'!$I$5:$I$34,">="&$B$21,'LANÇAMENTOS'!$I$5:$I$34,"<="&EOMONTH($B$21,0)),SUMIFS('LANÇAMENTOS'!$H$5:$H$34,'LANÇAMENTOS'!$B$5:$B$34,"Entrada",'LANÇAMENTOS'!$C$5:$C$34,$A29,'LANÇAMENTOS'!$I$5:$I$34,"<="&TODAY(),'LANÇAMENTOS'!$I$5:$I$34,">="&$B$21,'LANÇAMENTOS'!$I$5:$I$34,"<="&EOMONTH($B$21,0))),0)) | D29: =IF($A29="","",IFERROR(SUMIFS('LANÇAMENTOS'!$H$5:$H$34,'LANÇAMENTOS'!$B$5:$B$34,"Saída",'LANÇAMENTOS'!$C$5:$C$34,$A29,'LANÇAMENTOS'!$I$5:$I$34,">="&$B$21,'LANÇAMENTOS'!$I$5:$I$34,"<="&EOMONTH($B$21,0)),0)) | E29: =IF($A29="","",IFERROR(IF(modo_apuracao="Conferencia",SUMIFS('LANÇAMENTOS'!$H$5:$H$34,'LANÇAMENTOS'!$B$5:$B$34,"Saída",'LANÇAMENTOS'!$C$5:$C$34,$A29,'LANÇAMENTOS'!$K$5:$K$34,"Sim",'LANÇAMENTOS'!$I$5:$I$34,">="&$B$21,'LANÇAMENTOS'!$I$5:$I$34,"<="&EOMONTH($B$21,0)),SUMIFS('LANÇAMENTOS'!$H$5:$H$34,'LANÇAMENTOS'!$B$5:$B$34,"Saída",'LANÇAMENTOS'!$C$5:$C$34,$A29,'LANÇAMENTOS'!$I$5:$I$34,"<="&TODAY(),'LANÇAMENTOS'!$I$5:$I$34,">="&$B$21,'LANÇAMENTOS'!$I$5:$I$34,"<="&EOMONTH($B$21,0))),0))
A30: ='CONFIG'!$B$33 | B30: =IF($A30="","",IFERROR(SUMIFS('LANÇAMENTOS'!$H$5:$H$34,'LANÇAMENTOS'!$B$5:$B$34,"Entrada",'LANÇAMENTOS'!$C$5:$C$34,$A30,'LANÇAMENTOS'!$I$5:$I$34,">="&$B$21,'LANÇAMENTOS'!$I$5:$I$34,"<="&EOMONTH($B$21,0)),0)) | C30: =IF($A30="","",IFERROR(IF(modo_apuracao="Conferencia",SUMIFS('LANÇAMENTOS'!$H$5:$H$34,'LANÇAMENTOS'!$B$5:$B$34,"Entrada",'LANÇAMENTOS'!$C$5:$C$34,$A30,'LANÇAMENTOS'!$K$5:$K$34,"Sim",'LANÇAMENTOS'!$I$5:$I$34,">="&$B$21,'LANÇAMENTOS'!$I$5:$I$34,"<="&EOMONTH($B$21,0)),SUMIFS('LANÇAMENTOS'!$H$5:$H$34,'LANÇAMENTOS'!$B$5:$B$34,"Entrada",'LANÇAMENTOS'!$C$5:$C$34,$A30,'LANÇAMENTOS'!$I$5:$I$34,"<="&TODAY(),'LANÇAMENTOS'!$I$5:$I$34,">="&$B$21,'LANÇAMENTOS'!$I$5:$I$34,"<="&EOMONTH($B$21,0))),0)) | D30: =IF($A30="","",IFERROR(SUMIFS('LANÇAMENTOS'!$H$5:$H$34,'LANÇAMENTOS'!$B$5:$B$34,"Saída",'LANÇAMENTOS'!$C$5:$C$34,$A30,'LANÇAMENTOS'!$I$5:$I$34,">="&$B$21,'LANÇAMENTOS'!$I$5:$I$34,"<="&EOMONTH($B$21,0)),0)) | E30: =IF($A30="","",IFERROR(IF(modo_apuracao="Conferencia",SUMIFS('LANÇAMENTOS'!$H$5:$H$34,'LANÇAMENTOS'!$B$5:$B$34,"Saída",'LANÇAMENTOS'!$C$5:$C$34,$A30,'LANÇAMENTOS'!$K$5:$K$34,"Sim",'LANÇAMENTOS'!$I$5:$I$34,">="&$B$21,'LANÇAMENTOS'!$I$5:$I$34,"<="&EOMONTH($B$21,0)),SUMIFS('LANÇAMENTOS'!$H$5:$H$34,'LANÇAMENTOS'!$B$5:$B$34,"Saída",'LANÇAMENTOS'!$C$5:$C$34,$A30,'LANÇAMENTOS'!$I$5:$I$34,"<="&TODAY(),'LANÇAMENTOS'!$I$5:$I$34,">="&$B$21,'LANÇAMENTOS'!$I$5:$I$34,"<="&EOMONTH($B$21,0))),0))
A31: ='CONFIG'!$B$34 | B31: =IF($A31="","",IFERROR(SUMIFS('LANÇAMENTOS'!$H$5:$H$34,'LANÇAMENTOS'!$B$5:$B$34,"Entrada",'LANÇAMENTOS'!$C$5:$C$34,$A31,'LANÇAMENTOS'!$I$5:$I$34,">="&$B$21,'LANÇAMENTOS'!$I$5:$I$34,"<="&EOMONTH($B$21,0)),0)) | C31: =IF($A31="","",IFERROR(IF(modo_apuracao="Conferencia",SUMIFS('LANÇAMENTOS'!$H$5:$H$34,'LANÇAMENTOS'!$B$5:$B$34,"Entrada",'LANÇAMENTOS'!$C$5:$C$34,$A31,'LANÇAMENTOS'!$K$5:$K$34,"Sim",'LANÇAMENTOS'!$I$5:$I$34,">="&$B$21,'LANÇAMENTOS'!$I$5:$I$34,"<="&EOMONTH($B$21,0)),SUMIFS('LANÇAMENTOS'!$H$5:$H$34,'LANÇAMENTOS'!$B$5:$B$34,"Entrada",'LANÇAMENTOS'!$C$5:$C$34,$A31,'LANÇAMENTOS'!$I$5:$I$34,"<="&TODAY(),'LANÇAMENTOS'!$I$5:$I$34,">="&$B$21,'LANÇAMENTOS'!$I$5:$I$34,"<="&EOMONTH($B$21,0))),0)) | D31: =IF($A31="","",IFERROR(SUMIFS('LANÇAMENTOS'!$H$5:$H$34,'LANÇAMENTOS'!$B$5:$B$34,"Saída",'LANÇAMENTOS'!$C$5:$C$34,$A31,'LANÇAMENTOS'!$I$5:$I$34,">="&$B$21,'LANÇAMENTOS'!$I$5:$I$34,"<="&EOMONTH($B$21,0)),0)) | E31: =IF($A31="","",IFERROR(IF(modo_apuracao="Conferencia",SUMIFS('LANÇAMENTOS'!$H$5:$H$34,'LANÇAMENTOS'!$B$5:$B$34,"Saída",'LANÇAMENTOS'!$C$5:$C$34,$A31,'LANÇAMENTOS'!$K$5:$K$34,"Sim",'LANÇAMENTOS'!$I$5:$I$34,">="&$B$21,'LANÇAMENTOS'!$I$5:$I$34,"<="&EOMONTH($B$21,0)),SUMIFS('LANÇAMENTOS'!$H$5:$H$34,'LANÇAMENTOS'!$B$5:$B$34,"Saída",'LANÇAMENTOS'!$C$5:$C$34,$A31,'LANÇAMENTOS'!$I$5:$I$34,"<="&TODAY(),'LANÇAMENTOS'!$I$5:$I$34,">="&$B$21,'LANÇAMENTOS'!$I$5:$I$34,"<="&EOMONTH($B$21,0))),0))
A32: ='CONFIG'!$B$35 | B32: =IF($A32="","",IFERROR(SUMIFS('LANÇAMENTOS'!$H$5:$H$34,'LANÇAMENTOS'!$B$5:$B$34,"Entrada",'LANÇAMENTOS'!$C$5:$C$34,$A32,'LANÇAMENTOS'!$I$5:$I$34,">="&$B$21,'LANÇAMENTOS'!$I$5:$I$34,"<="&EOMONTH($B$21,0)),0)) | C32: =IF($A32="","",IFERROR(IF(modo_apuracao="Conferencia",SUMIFS('LANÇAMENTOS'!$H$5:$H$34,'LANÇAMENTOS'!$B$5:$B$34,"Entrada",'LANÇAMENTOS'!$C$5:$C$34,$A32,'LANÇAMENTOS'!$K$5:$K$34,"Sim",'LANÇAMENTOS'!$I$5:$I$34,">="&$B$21,'LANÇAMENTOS'!$I$5:$I$34,"<="&EOMONTH($B$21,0)),SUMIFS('LANÇAMENTOS'!$H$5:$H$34,'LANÇAMENTOS'!$B$5:$B$34,"Entrada",'LANÇAMENTOS'!$C$5:$C$34,$A32,'LANÇAMENTOS'!$I$5:$I$34,"<="&TODAY(),'LANÇAMENTOS'!$I$5:$I$34,">="&$B$21,'LANÇAMENTOS'!$I$5:$I$34,"<="&EOMONTH($B$21,0))),0)) | D32: =IF($A32="","",IFERROR(SUMIFS('LANÇAMENTOS'!$H$5:$H$34,'LANÇAMENTOS'!$B$5:$B$34,"Saída",'LANÇAMENTOS'!$C$5:$C$34,$A32,'LANÇAMENTOS'!$I$5:$I$34,">="&$B$21,'LANÇAMENTOS'!$I$5:$I$34,"<="&EOMONTH($B$21,0)),0)) | E32: =IF($A32="","",IFERROR(IF(modo_apuracao="Conferencia",SUMIFS('LANÇAMENTOS'!$H$5:$H$34,'LANÇAMENTOS'!$B$5:$B$34,"Saída",'LANÇAMENTOS'!$C$5:$C$34,$A32,'LANÇAMENTOS'!$K$5:$K$34,"Sim",'LANÇAMENTOS'!$I$5:$I$34,">="&$B$21,'LANÇAMENTOS'!$I$5:$I$34,"<="&EOMONTH($B$21,0)),SUMIFS('LANÇAMENTOS'!$H$5:$H$34,'LANÇAMENTOS'!$B$5:$B$34,"Saída",'LANÇAMENTOS'!$C$5:$C$34,$A32,'LANÇAMENTOS'!$I$5:$I$34,"<="&TODAY(),'LANÇAMENTOS'!$I$5:$I$34,">="&$B$21,'LANÇAMENTOS'!$I$5:$I$34,"<="&EOMONTH($B$21,0))),0))
A33: ='CONFIG'!$B$36 | B33: =IF($A33="","",IFERROR(SUMIFS('LANÇAMENTOS'!$H$5:$H$34,'LANÇAMENTOS'!$B$5:$B$34,"Entrada",'LANÇAMENTOS'!$C$5:$C$34,$A33,'LANÇAMENTOS'!$I$5:$I$34,">="&$B$21,'LANÇAMENTOS'!$I$5:$I$34,"<="&EOMONTH($B$21,0)),0)) | C33: =IF($A33="","",IFERROR(IF(modo_apuracao="Conferencia",SUMIFS('LANÇAMENTOS'!$H$5:$H$34,'LANÇAMENTOS'!$B$5:$B$34,"Entrada",'LANÇAMENTOS'!$C$5:$C$34,$A33,'LANÇAMENTOS'!$K$5:$K$34,"Sim",'LANÇAMENTOS'!$I$5:$I$34,">="&$B$21,'LANÇAMENTOS'!$I$5:$I$34,"<="&EOMONTH($B$21,0)),SUMIFS('LANÇAMENTOS'!$H$5:$H$34,'LANÇAMENTOS'!$B$5:$B$34,"Entrada",'LANÇAMENTOS'!$C$5:$C$34,$A33,'LANÇAMENTOS'!$I$5:$I$34,"<="&TODAY(),'LANÇAMENTOS'!$I$5:$I$34,">="&$B$21,'LANÇAMENTOS'!$I$5:$I$34,"<="&EOMONTH($B$21,0))),0)) | D33: =IF($A33="","",IFERROR(SUMIFS('LANÇAMENTOS'!$H$5:$H$34,'LANÇAMENTOS'!$B$5:$B$34,"Saída",'LANÇAMENTOS'!$C$5:$C$34,$A33,'LANÇAMENTOS'!$I$5:$I$34,">="&$B$21,'LANÇAMENTOS'!$I$5:$I$34,"<="&EOMONTH($B$21,0)),0)) | E33: =IF($A33="","",IFERROR(IF(modo_apuracao="Conferencia",SUMIFS('LANÇAMENTOS'!$H$5:$H$34,'LANÇAMENTOS'!$B$5:$B$34,"Saída",'LANÇAMENTOS'!$C$5:$C$34,$A33,'LANÇAMENTOS'!$K$5:$K$34,"Sim",'LANÇAMENTOS'!$I$5:$I$34,">="&$B$21,'LANÇAMENTOS'!$I$5:$I$34,"<="&EOMONTH($B$21,0)),SUMIFS('LANÇAMENTOS'!$H$5:$H$34,'LANÇAMENTOS'!$B$5:$B$34,"Saída",'LANÇAMENTOS'!$C$5:$C$34,$A33,'LANÇAMENTOS'!$I$5:$I$34,"<="&TODAY(),'LANÇAMENTOS'!$I$5:$I$34,">="&$B$21,'LANÇAMENTOS'!$I$5:$I$34,"<="&EOMONTH($B$21,0))),0))
A34: ='CONFIG'!$B$37 | B34: =IF($A34="","",IFERROR(SUMIFS('LANÇAMENTOS'!$H$5:$H$34,'LANÇAMENTOS'!$B$5:$B$34,"Entrada",'LANÇAMENTOS'!$C$5:$C$34,$A34,'LANÇAMENTOS'!$I$5:$I$34,">="&$B$21,'LANÇAMENTOS'!$I$5:$I$34,"<="&EOMONTH($B$21,0)),0)) | C34: =IF($A34="","",IFERROR(IF(modo_apuracao="Conferencia",SUMIFS('LANÇAMENTOS'!$H$5:$H$34,'LANÇAMENTOS'!$B$5:$B$34,"Entrada",'LANÇAMENTOS'!$C$5:$C$34,$A34,'LANÇAMENTOS'!$K$5:$K$34,"Sim",'LANÇAMENTOS'!$I$5:$I$34,">="&$B$21,'LANÇAMENTOS'!$I$5:$I$34,"<="&EOMONTH($B$21,0)),SUMIFS('LANÇAMENTOS'!$H$5:$H$34,'LANÇAMENTOS'!$B$5:$B$34,"Entrada",'LANÇAMENTOS'!$C$5:$C$34,$A34,'LANÇAMENTOS'!$I$5:$I$34,"<="&TODAY(),'LANÇAMENTOS'!$I$5:$I$34,">="&$B$21,'LANÇAMENTOS'!$I$5:$I$34,"<="&EOMONTH($B$21,0))),0)) | D34: =IF($A34="","",IFERROR(SUMIFS('LANÇAMENTOS'!$H$5:$H$34,'LANÇAMENTOS'!$B$5:$B$34,"Saída",'LANÇAMENTOS'!$C$5:$C$34,$A34,'LANÇAMENTOS'!$I$5:$I$34,">="&$B$21,'LANÇAMENTOS'!$I$5:$I$34,"<="&EOMONTH($B$21,0)),0)) | E34: =IF($A34="","",IFERROR(IF(modo_apuracao="Conferencia",SUMIFS('LANÇAMENTOS'!$H$5:$H$34,'LANÇAMENTOS'!$B$5:$B$34,"Saída",'LANÇAMENTOS'!$C$5:$C$34,$A34,'LANÇAMENTOS'!$K$5:$K$34,"Sim",'LANÇAMENTOS'!$I$5:$I$34,">="&$B$21,'LANÇAMENTOS'!$I$5:$I$34,"<="&EOMONTH($B$21,0)),SUMIFS('LANÇAMENTOS'!$H$5:$H$34,'LANÇAMENTOS'!$B$5:$B$34,"Saída",'LANÇAMENTOS'!$C$5:$C$34,$A34,'LANÇAMENTOS'!$I$5:$I$34,"<="&TODAY(),'LANÇAMENTOS'!$I$5:$I$34,">="&$B$21,'LANÇAMENTOS'!$I$5:$I$34,"<="&EOMONTH($B$21,0))),0))
A35: ='CONFIG'!$B$38 | B35: =IF($A35="","",IFERROR(SUMIFS('LANÇAMENTOS'!$H$5:$H$34,'LANÇAMENTOS'!$B$5:$B$34,"Entrada",'LANÇAMENTOS'!$C$5:$C$34,$A35,'LANÇAMENTOS'!$I$5:$I$34,">="&$B$21,'LANÇAMENTOS'!$I$5:$I$34,"<="&EOMONTH($B$21,0)),0)) | C35: =IF($A35="","",IFERROR(IF(modo_apuracao="Conferencia",SUMIFS('LANÇAMENTOS'!$H$5:$H$34,'LANÇAMENTOS'!$B$5:$B$34,"Entrada",'LANÇAMENTOS'!$C$5:$C$34,$A35,'LANÇAMENTOS'!$K$5:$K$34,"Sim",'LANÇAMENTOS'!$I$5:$I$34,">="&$B$21,'LANÇAMENTOS'!$I$5:$I$34,"<="&EOMONTH($B$21,0)),SUMIFS('LANÇAMENTOS'!$H$5:$H$34,'LANÇAMENTOS'!$B$5:$B$34,"Entrada",'LANÇAMENTOS'!$C$5:$C$34,$A35,'LANÇAMENTOS'!$I$5:$I$34,"<="&TODAY(),'LANÇAMENTOS'!$I$5:$I$34,">="&$B$21,'LANÇAMENTOS'!$I$5:$I$34,"<="&EOMONTH($B$21,0))),0)) | D35: =IF($A35="","",IFERROR(SUMIFS('LANÇAMENTOS'!$H$5:$H$34,'LANÇAMENTOS'!$B$5:$B$34,"Saída",'LANÇAMENTOS'!$C$5:$C$34,$A35,'LANÇAMENTOS'!$I$5:$I$34,">="&$B$21,'LANÇAMENTOS'!$I$5:$I$34,"<="&EOMONTH($B$21,0)),0)) | E35: =IF($A35="","",IFERROR(IF(modo_apuracao="Conferencia",SUMIFS('LANÇAMENTOS'!$H$5:$H$34,'LANÇAMENTOS'!$B$5:$B$34,"Saída",'LANÇAMENTOS'!$C$5:$C$34,$A35,'LANÇAMENTOS'!$K$5:$K$34,"Sim",'LANÇAMENTOS'!$I$5:$I$34,">="&$B$21,'LANÇAMENTOS'!$I$5:$I$34,"<="&EOMONTH($B$21,0)),SUMIFS('LANÇAMENTOS'!$H$5:$H$34,'LANÇAMENTOS'!$B$5:$B$34,"Saída",'LANÇAMENTOS'!$C$5:$C$34,$A35,'LANÇAMENTOS'!$I$5:$I$34,"<="&TODAY(),'LANÇAMENTOS'!$I$5:$I$34,">="&$B$21,'LANÇAMENTOS'!$I$5:$I$34,"<="&EOMONTH($B$21,0))),0))
A36: ='CONFIG'!$B$39 | B36: =IF($A36="","",IFERROR(SUMIFS('LANÇAMENTOS'!$H$5:$H$34,'LANÇAMENTOS'!$B$5:$B$34,"Entrada",'LANÇAMENTOS'!$C$5:$C$34,$A36,'LANÇAMENTOS'!$I$5:$I$34,">="&$B$21,'LANÇAMENTOS'!$I$5:$I$34,"<="&EOMONTH($B$21,0)),0)) | C36: =IF($A36="","",IFERROR(IF(modo_apuracao="Conferencia",SUMIFS('LANÇAMENTOS'!$H$5:$H$34,'LANÇAMENTOS'!$B$5:$B$34,"Entrada",'LANÇAMENTOS'!$C$5:$C$34,$A36,'LANÇAMENTOS'!$K$5:$K$34,"Sim",'LANÇAMENTOS'!$I$5:$I$34,">="&$B$21,'LANÇAMENTOS'!$I$5:$I$34,"<="&EOMONTH($B$21,0)),SUMIFS('LANÇAMENTOS'!$H$5:$H$34,'LANÇAMENTOS'!$B$5:$B$34,"Entrada",'LANÇAMENTOS'!$C$5:$C$34,$A36,'LANÇAMENTOS'!$I$5:$I$34,"<="&TODAY(),'LANÇAMENTOS'!$I$5:$I$34,">="&$B$21,'LANÇAMENTOS'!$I$5:$I$34,"<="&EOMONTH($B$21,0))),0)) | D36: =IF($A36="","",IFERROR(SUMIFS('LANÇAMENTOS'!$H$5:$H$34,'LANÇAMENTOS'!$B$5:$B$34,"Saída",'LANÇAMENTOS'!$C$5:$C$34,$A36,'LANÇAMENTOS'!$I$5:$I$34,">="&$B$21,'LANÇAMENTOS'!$I$5:$I$34,"<="&EOMONTH($B$21,0)),0)) | E36: =IF($A36="","",IFERROR(IF(modo_apuracao="Conferencia",SUMIFS('LANÇAMENTOS'!$H$5:$H$34,'LANÇAMENTOS'!$B$5:$B$34,"Saída",'LANÇAMENTOS'!$C$5:$C$34,$A36,'LANÇAMENTOS'!$K$5:$K$34,"Sim",'LANÇAMENTOS'!$I$5:$I$34,">="&$B$21,'LANÇAMENTOS'!$I$5:$I$34,"<="&EOMONTH($B$21,0)),SUMIFS('LANÇAMENTOS'!$H$5:$H$34,'LANÇAMENTOS'!$B$5:$B$34,"Saída",'LANÇAMENTOS'!$C$5:$C$34,$A36,'LANÇAMENTOS'!$I$5:$I$34,"<="&TODAY(),'LANÇAMENTOS'!$I$5:$I$34,">="&$B$21,'LANÇAMENTOS'!$I$5:$I$34,"<="&EOMONTH($B$21,0))),0))
A37: ='CONFIG'!$B$40 | B37: =IF($A37="","",IFERROR(SUMIFS('LANÇAMENTOS'!$H$5:$H$34,'LANÇAMENTOS'!$B$5:$B$34,"Entrada",'LANÇAMENTOS'!$C$5:$C$34,$A37,'LANÇAMENTOS'!$I$5:$I$34,">="&$B$21,'LANÇAMENTOS'!$I$5:$I$34,"<="&EOMONTH($B$21,0)),0)) | C37: =IF($A37="","",IFERROR(IF(modo_apuracao="Conferencia",SUMIFS('LANÇAMENTOS'!$H$5:$H$34,'LANÇAMENTOS'!$B$5:$B$34,"Entrada",'LANÇAMENTOS'!$C$5:$C$34,$A37,'LANÇAMENTOS'!$K$5:$K$34,"Sim",'LANÇAMENTOS'!$I$5:$I$34,">="&$B$21,'LANÇAMENTOS'!$I$5:$I$34,"<="&EOMONTH($B$21,0)),SUMIFS('LANÇAMENTOS'!$H$5:$H$34,'LANÇAMENTOS'!$B$5:$B$34,"Entrada",'LANÇAMENTOS'!$C$5:$C$34,$A37,'LANÇAMENTOS'!$I$5:$I$34,"<="&TODAY(),'LANÇAMENTOS'!$I$5:$I$34,">="&$B$21,'LANÇAMENTOS'!$I$5:$I$34,"<="&EOMONTH($B$21,0))),0)) | D37: =IF($A37="","",IFERROR(SUMIFS('LANÇAMENTOS'!$H$5:$H$34,'LANÇAMENTOS'!$B$5:$B$34,"Saída",'LANÇAMENTOS'!$C$5:$C$34,$A37,'LANÇAMENTOS'!$I$5:$I$34,">="&$B$21,'LANÇAMENTOS'!$I$5:$I$34,"<="&EOMONTH($B$21,0)),0)) | E37: =IF($A37="","",IFERROR(IF(modo_apuracao="Conferencia",SUMIFS('LANÇAMENTOS'!$H$5:$H$34,'LANÇAMENTOS'!$B$5:$B$34,"Saída",'LANÇAMENTOS'!$C$5:$C$34,$A37,'LANÇAMENTOS'!$K$5:$K$34,"Sim",'LANÇAMENTOS'!$I$5:$I$34,">="&$B$21,'LANÇAMENTOS'!$I$5:$I$34,"<="&EOMONTH($B$21,0)),SUMIFS('LANÇAMENTOS'!$H$5:$H$34,'LANÇAMENTOS'!$B$5:$B$34,"Saída",'LANÇAMENTOS'!$C$5:$C$34,$A37,'LANÇAMENTOS'!$I$5:$I$34,"<="&TODAY(),'LANÇAMENTOS'!$I$5:$I$34,">="&$B$21,'LANÇAMENTOS'!$I$5:$I$34,"<="&EOMONTH($B$21,0))),0))
A38: ='CONFIG'!$B$41 | B38: =IF($A38="","",IFERROR(SUMIFS('LANÇAMENTOS'!$H$5:$H$34,'LANÇAMENTOS'!$B$5:$B$34,"Entrada",'LANÇAMENTOS'!$C$5:$C$34,$A38,'LANÇAMENTOS'!$I$5:$I$34,">="&$B$21,'LANÇAMENTOS'!$I$5:$I$34,"<="&EOMONTH($B$21,0)),0)) | C38: =IF($A38="","",IFERROR(IF(modo_apuracao="Conferencia",SUMIFS('LANÇAMENTOS'!$H$5:$H$34,'LANÇAMENTOS'!$B$5:$B$34,"Entrada",'LANÇAMENTOS'!$C$5:$C$34,$A38,'LANÇAMENTOS'!$K$5:$K$34,"Sim",'LANÇAMENTOS'!$I$5:$I$34,">="&$B$21,'LANÇAMENTOS'!$I$5:$I$34,"<="&EOMONTH($B$21,0)),SUMIFS('LANÇAMENTOS'!$H$5:$H$34,'LANÇAMENTOS'!$B$5:$B$34,"Entrada",'LANÇAMENTOS'!$C$5:$C$34,$A38,'LANÇAMENTOS'!$I$5:$I$34,"<="&TODAY(),'LANÇAMENTOS'!$I$5:$I$34,">="&$B$21,'LANÇAMENTOS'!$I$5:$I$34,"<="&EOMONTH($B$21,0))),0)) | D38: =IF($A38="","",IFERROR(SUMIFS('LANÇAMENTOS'!$H$5:$H$34,'LANÇAMENTOS'!$B$5:$B$34,"Saída",'LANÇAMENTOS'!$C$5:$C$34,$A38,'LANÇAMENTOS'!$I$5:$I$34,">="&$B$21,'LANÇAMENTOS'!$I$5:$I$34,"<="&EOMONTH($B$21,0)),0)) | E38: =IF($A38="","",IFERROR(IF(modo_apuracao="Conferencia",SUMIFS('LANÇAMENTOS'!$H$5:$H$34,'LANÇAMENTOS'!$B$5:$B$34,"Saída",'LANÇAMENTOS'!$C$5:$C$34,$A38,'LANÇAMENTOS'!$K$5:$K$34,"Sim",'LANÇAMENTOS'!$I$5:$I$34,">="&$B$21,'LANÇAMENTOS'!$I$5:$I$34,"<="&EOMONTH($B$21,0)),SUMIFS('LANÇAMENTOS'!$H$5:$H$34,'LANÇAMENTOS'!$B$5:$B$34,"Saída",'LANÇAMENTOS'!$C$5:$C$34,$A38,'LANÇAMENTOS'!$I$5:$I$34,"<="&TODAY(),'LANÇAMENTOS'!$I$5:$I$34,">="&$B$21,'LANÇAMENTOS'!$I$5:$I$34,"<="&EOMONTH($B$21,0))),0))

Sheet DASHBOARD
A1: W.D.S. — DASHBOARD
A2: Ir para: | B2: INÍCIO | C2: CONFIG | D2: LANÇAMENTOS | E2: CONTAS A PAGAR-RECEBER | F2: FLUXO DE CAIXA | G2: RELATÓRIO | H2: DÚVIDAS
A3: Indicadores e gráficos calculados automaticamente. Nada aqui é editável.
A5: Saldo Atual | B5: =saldo_inicial+$L$5-$L$6 | J5: =DATE(YEAR(TODAY()),MONTH(TODAY()),1) | L5: =IFERROR(IF(modo_apuracao="Conferencia",SUMIFS('LANÇAMENTOS'!$H$5:$H$34,'LANÇAMENTOS'!$B$5:$B$34,"Entrada",'LANÇAMENTOS'!$K$5:$K$34,"Sim"),SUMIFS('LANÇAMENTOS'!$H$5:$H$34,'LANÇAMENTOS'!$B$5:$B$34,"Entrada",'LANÇAMENTOS'!$I$5:$I$34,"<="&TODAY())),0)
A6: Entradas do Mês | B6: =IFERROR(IF(modo_apuracao="Conferencia",SUMIFS('LANÇAMENTOS'!$H$5:$H$34,'LANÇAMENTOS'!$B$5:$B$34,"Entrada",'LANÇAMENTOS'!$K$5:$K$34,"Sim",'LANÇAMENTOS'!$I$5:$I$34,">="&$J$5,'LANÇAMENTOS'!$I$5:$I$34,"<="&$J$6),SUMIFS('LANÇAMENTOS'!$H$5:$H$34,'LANÇAMENTOS'!$B$5:$B$34,"Entrada",'LANÇAMENTOS'!$I$5:$I$34,"<="&TODAY(),'LANÇAMENTOS'!$I$5:$I$34,">="&$J$5,'LANÇAMENTOS'!$I$5:$I$34,"<="&$J$6)),0) | J6: =EOMONTH(J5,0) | L6: =IFERROR(IF(modo_apuracao="Conferencia",SUMIFS('LANÇAMENTOS'!$H$5:$H$34,'LANÇAMENTOS'!$B$5:$B$34,"Saída",'LANÇAMENTOS'!$K$5:$K$34,"Sim"),SUMIFS('LANÇAMENTOS'!$H$5:$H$34,'LANÇAMENTOS'!$B$5:$B$34,"Saída",'LANÇAMENTOS'!$I$5:$I$34,"<="&TODAY())),0)
A7: Saídas do Mês | B7: =IFERROR(IF(modo_apuracao="Conferencia",SUMIFS('LANÇAMENTOS'!$H$5:$H$34,'LANÇAMENTOS'!$B$5:$B$34,"Saída",'LANÇAMENTOS'!$K$5:$K$34,"Sim",'LANÇAMENTOS'!$I$5:$I$34,">="&$J$5,'LANÇAMENTOS'!$I$5:$I$34,"<="&$J$6),SUMIFS('LANÇAMENTOS'!$H$5:$H$34,'LANÇAMENTOS'!$B$5:$B$34,"Saída",'LANÇAMENTOS'!$I$5:$I$34,"<="&TODAY(),'LANÇAMENTOS'!$I$5:$I$34,">="&$J$5,'LANÇAMENTOS'!$I$5:$I$34,"<="&$J$6)),0)
A8: Saldo Projetado Fim do Mês | B8: =$B$5+((IFERROR(SUMIFS('LANÇAMENTOS'!$H$5:$H$34,'LANÇAMENTOS'!$B$5:$B$34,"Entrada",'LANÇAMENTOS'!$I$5:$I$34,">="&$J$5,'LANÇAMENTOS'!$I$5:$I$34,"<="&$J$6),0))-($B$6))-((IFERROR(SUMIFS('LANÇAMENTOS'!$H$5:$H$34,'LANÇAMENTOS'!$B$5:$B$34,"Saída",'LANÇAMENTOS'!$I$5:$I$34,">="&$J$5,'LANÇAMENTOS'!$I$5:$I$34,"<="&$J$6),0))-($B$7))
A11: Dados auxiliares dos gráficos (não editar)
A12: Mês | B12: Entradas | C12: Saídas
A13: =DATE(YEAR(TODAY()),MONTH(TODAY())-5,1) | B13: =IFERROR(IF(modo_apuracao="Conferencia",SUMIFS('LANÇAMENTOS'!$H$5:$H$34,'LANÇAMENTOS'!$B$5:$B$34,"Entrada",'LANÇAMENTOS'!$K$5:$K$34,"Sim",'LANÇAMENTOS'!$I$5:$I$34,">="&(DATE(YEAR(TODAY()),MONTH(TODAY())-5,1)),'LANÇAMENTOS'!$I$5:$I$34,"<="&(EOMONTH(DATE(YEAR(TODAY()),MONTH(TODAY())-5,1),0))),SUMIFS('LANÇAMENTOS'!$H$5:$H$34,'LANÇAMENTOS'!$B$5:$B$34,"Entrada",'LANÇAMENTOS'!$I$5:$I$34,"<="&TODAY(),'LANÇAMENTOS'!$I$5:$I$34,">="&(DATE(YEAR(TODAY()),MONTH(TODAY())-5,1)),'LANÇAMENTOS'!$I$5:$I$34,"<="&(EOMONTH(DATE(YEAR(TODAY()),MONTH(TODAY())-5,1),0)))),0) | C13: =IFERROR(IF(modo_apuracao="Conferencia",SUMIFS('LANÇAMENTOS'!$H$5:$H$34,'LANÇAMENTOS'!$B$5:$B$34,"Saída",'LANÇAMENTOS'!$K$5:$K$34,"Sim",'LANÇAMENTOS'!$I$5:$I$34,">="&(DATE(YEAR(TODAY()),MONTH(TODAY())-5,1)),'LANÇAMENTOS'!$I$5:$I$34,"<="&(EOMONTH(DATE(YEAR(TODAY()),MONTH(TODAY())-5,1),0))),SUMIFS('LANÇAMENTOS'!$H$5:$H$34,'LANÇAMENTOS'!$B$5:$B$34,"Saída",'LANÇAMENTOS'!$I$5:$I$34,"<="&TODAY(),'LANÇAMENTOS'!$I$5:$I$34,">="&(DATE(YEAR(TODAY()),MONTH(TODAY())-5,1)),'LANÇAMENTOS'!$I$5:$I$34,"<="&(EOMONTH(DATE(YEAR(TODAY()),MONTH(TODAY())-5,1),0)))),0)
